Workbook
Name L_site: Lists!$A$2:$A$24
Name L_side: Lists!$D$2:$D$5
Name L_hist: Lists!$G$2:$G$16
Name L_T: Lists!$I$2:$I$10
Name L_N: Lists!$K$2:$K$11
Name L_M: Lists!$M$2:$M$3
Name L_stage: Lists!$O$2:$O$9
Name L_marker: Lists!$Q$2:$Q$5
Name L_yn: Lists!$S$2:$S$3
Name L_ynu: Lists!$U$2:$U$4
Name L_sex: Lists!$W$2:$W$3
Name L_ecog: Lists!$Y$2:$Y$7
Name L_smoke: Lists!$AA$2:$AA$5
Name L_alc: Lists!$AC$2:$AC$5
Name L_ace: Lists!$AE$2:$AE$6
Name L_cci: Lists!$AG$2:$AG$8
Name L_dist: Lists!$AI$2:$AI$6
Name L_lang: Lists!$AK$2:$AK$7
Name L_ses: Lists!$AM$2:$AM$5
Name L_insur: Lists!$AO$2:$AO$5
Name L_refsrc: Lists!$AQ$2:$AQ$10
Name L_mod: Lists!$AS$2:$AS$9
Name L_txsite: Lists!$AU$2:$AU$6
Name L_dreason: Lists!$AW$2:$AW$22
Name L_dphase: Lists!$AY$2:$AY$6
Name L_dsrc: Lists!$BA$2:$BA$6
Name L_excl: Lists!$BC$2:$BC$9
Name L_vital: Lists!$BE$2:$BE$4

Sheet README
A1: מאבחנה לטיפול ראשוני — גיליון איסוף נתונים
A2: מחקר רטרוספקטיבי · מחלקת אא״ג וכירורגיית ראש-צוואר, מרכז רפואי מאיר | B2: קוהורטה רטרוספקטיבית רצופה · הגיליון בנוי לאיסוף לפי הפרמטרים שנמדדו במחקרים המובילים (גיליון Parameters)
A4: מספר מחקר | B4: מזהה רשמי אחד לכל מטופל, באנגלית: RET-23-014-GLT-L-03
A5: RET | B5: הזרוע הרטרוספקטיבית — כדי שלא תתבלבל עם מספרי הפיילוט הפרוספקטיבי (ENT-…)
A6: 23 | B6: שנת דוח הפתולוגיה הממאירה
A7: 014 | B7: מספר רץ — הוא שמבטיח ייחודיות
A8: GLT | B8: קוד אתר הגידול (הרשימה המלאה בגיליון Lists)
A9: L | B9: צד: R ימין · L שמאל · M קו אמצע · B דו-צדדי
A10: 03 | B10: חודש דוח הפתולוגיה
A11: נוצר אוטומטית | B11: העמודה הראשונה בונה את המספר ברגע שמוזנים מספר רץ, אתר, צד ותאריך פתולוגיה. לאחר ההקצאה הוא קבוע — תיקון אתר מתועד בהערות ולא משנה את המספר.
A13: כללים
A14: 1 | B14: אין בקובץ שם, תעודת זהות, תאריך לידה, כתובת או טלפון. קובץ המפתח בין מספר המחקר לזהות נשמר בנפרד, על מחשב כללית בלבד, ואינו חלק מקובץ זה.
A15: 2 | B15: הקובץ נשמר על מחשב כללית בלבד ואינו יוצא ממנו. עד לאישור ועדת הלסינקי ואבטחת המידע — נתונים סינתטיים בלבד.
A16: 3 | B16: תאריכים בפורמט dd/mm/yyyy. שדות הרשימה מקבלים ערכים מהרשימה בלבד.
A17: 4 | B17: שדה שאין לו מקור ברשומה — משאירים ריק או מסמנים ״לא מתועד״. אין להשלים מהזיכרון.
A18: 5 | B18: עשרה אחוזים מהתיקים ייאספו בשנית בידי חוקר שני, ויחושב מדד התאמה — ICC לתאריכים וקאפה לשדות הקטגוריים.
A20: שני עוגני אבחנה, בכוונה
A21: מדוע | B21: הספרות משתמשת בשני עוגנים שונים: תאריך הביופסיה (Tsai 2017) ותאריך דוח הפתולוגיה (Liao 2019, Amarillo 2024). המטה-אנליזה מצביעה במפורש על חוסר האחידות הזה כפגם מתודולוגי.
A22: מה עושים | B22: נאספים שניהם. התוצא הראשוני נמדד מדוח הפתולוגיה; ניתוח הרגישות חוזר על הכל מתאריך הביופסיה. כך התוצאה ניתנת להשוואה לשתי המשפחות.
A24: מקרא צבעים
A25: צהוב | B25: שדה להזנה
A26: אפור | B26: מחושב אוטומטית — לא לגעת
A27: כחול | B27: שורת הדוגמה הסינתטית (שורה 5) — אינה נספרת בסיכום
A28: אדום | B28: מרווח שלילי (תאריכים הפוכים) או מספר מחקר כפול
A30: הגיליונות
A31: Summary | B31: סיכום התוצאים — חציונים, רבעונים, ספי הסף ועמידה ביעדים. מתעדכן אוטומטית.
A32: Patients | B32: 200 שורות — שורה למטופל: זיהוי, דמוגרפיה, גידול, מסלול, תאריכים, מרווחים מחושבים.
A33: Delays | B33: יומן אירועי עיכוב — אירוע בשורה, עם המקטע, הסיבה, הסיווג ומשך ההמתנה.
A34: Parameters | B34: מה נמדד בכל אחד מ-22 המחקרים המובילים: העוגנים, המשתנים, התוצאים, הספים והממצאים — כולל ממצאי האפס.
A35: Dictionary | B35: הגדרת כל שדה, סוגו, והמחקר שבגללו הוא נאסף.
A36: Lists | B36: ערכי הרשימות הנפתחות.

Sheet Summary
A1: סיכום התוצאים — מתעדכן אוטומטית | D1: כל הערכים מחושבים משורות 6 ומטה בגיליון Patients. שורת הדוגמה אינה נספרת.
A3: אוכלוסייה | B3: ערך | C3: n | D3: מקור / יעד
A4: שורות שהוזנו | B4: =COUNTIF(Patients!$A$6:$A$205,"?*")
A5: נכללו בניתוח | B5: =COUNTIFS(Patients!$F$6:$F$205,"כן") | D5: תרשים STROBE — ההוצאות בעמודת ״סיבת הוצאה״.
A6: עם תוצא ראשוני מלא | B6: =COUNT(Patients!$BR$6:$BR$205)
A7: גיל, חציון | B7: =IFERROR(MEDIAN(Patients!$H$6:$H$205),"")
A8: שיעור גברים | B8: =IFERROR(COUNTIF(Patients!$I$6:$I$205,"ז")/COUNTIF(Patients!$I$6:$I$205,"?*"),"")
A9: שיעור מחלה מתקדמת (III–IV) | B9: =IFERROR(AVERAGE(Patients!$Z$6:$Z$205),"") | D9: החלוקה של Amarillo 2024.
A10: התוצא הראשוני — אבחנה ← טיפול (ימים) | B10: ערך | C10: n | D10: מקור / יעד
A11: חציון | B11: =IF(COUNT(Patients!$BR$6:$BR$205)=0,"",MEDIAN(Patients!$BR$6:$BR$205)) | C11: =COUNT(Patients!$BR$6:$BR$205)
A12: רבעון ראשון (Q1) | B12: =IF(COUNT(Patients!$BR$6:$BR$205)=0,"",QUARTILE.INC(Patients!$BR$6:$BR$205,1))
A13: רבעון שלישי (Q3) | B13: =IF(COUNT(Patients!$BR$6:$BR$205)=0,"",QUARTILE.INC(Patients!$BR$6:$BR$205,3))
A14: ממוצע | B14: =IF(COUNT(Patients!$BR$6:$BR$205)=0,"",AVERAGE(Patients!$BR$6:$BR$205))
A15: סטיית תקן | B15: =IF(COUNT(Patients!$BR$6:$BR$205)=0,"",STDEV.S(Patients!$BR$6:$BR$205))
A16: מינימום | B16: =IF(COUNT(Patients!$BR$6:$BR$205)=0,"",MIN(Patients!$BR$6:$BR$205))
A17: מקסימום | B17: =IF(COUNT(Patients!$BR$6:$BR$205)=0,"",MAX(Patients!$BR$6:$BR$205))
A18: חציון התוצא הראשוני לפי מודאליות | B18: ערך | C18: n | D18: מקור / יעד
A19: ניתוח | B19: {=IFERROR(MEDIAN(IF(Patients!$BE$6:$BE$205="ניתוח",IF(ISNUMBER(Patients!$BR$6:$BR$205),Patients!$BR$6:$BR$205))),"")} | C19: =COUNTIF(Patients!$BE$6:$BE$205,"ניתוח")
A20: הקרנות | B20: {=IFERROR(MEDIAN(IF(Patients!$BE$6:$BE$205="הקרנות",IF(ISNUMBER(Patients!$BR$6:$BR$205),Patients!$BR$6:$BR$205))),"")} | C20: =COUNTIF(Patients!$BE$6:$BE$205,"הקרנות") | D20: Schoonbeek 2021: הקרנות ראשוניות — OR 9.93 לעיכוב.
A21: כימו-הקרנות | B21: {=IFERROR(MEDIAN(IF(Patients!$BE$6:$BE$205="כימו-הקרנות",IF(ISNUMBER(Patients!$BR$6:$BR$205),Patients!$BR$6:$BR$205))),"")} | C21: =COUNTIF(Patients!$BE$6:$BE$205,"כימו-הקרנות")
A22: ספי הסף מהספרות | B22: שיעור | C22: n | D22: המחקר שקבע את הסף
A23: טופלו ≤ 30 יום | B23: =IFERROR(AVERAGE(Patients!$BZ$6:$BZ$205),"") | C23: =SUM(Patients!$BZ$6:$BZ$205) | D23: סף המטה-אנליזה: aHR 1.09 (1.06–1.13) לטובת ≤30 יום.
A24: מעל 40.5 יום | B24: =IFERROR(AVERAGE(Patients!$CA$6:$CA$205),"") | C24: =SUM(Patients!$CA$6:$CA$205) | D24: Amarillo 2024, מונטווידאו, n=377 — הסף שהופק ב-RPA.
A25: מעל 60 יום | B25: =IFERROR(AVERAGE(Patients!$CB$6:$CB$205),"") | C25: =SUM(Patients!$CB$6:$CB$205) | D25: Liao 2019, n=956 — HR 1.69 (1.32–2.18) לתמותה.
A26: מעל 67 יום | B26: =IFERROR(AVERAGE(Patients!$CC$6:$CC$205),"") | C26: =SUM(Patients!$CC$6:$CC$205) | D26: Murphy 2016, NCDB n=51,655 · Rygalski 2021, n=37,730.
A27: מקטעי המסלול — חציון (ימים) | B27: חציון | C27: n | D27: יעד מפורסם
A28: הפניה ← ייעוץ | B28: =IFERROR(MEDIAN(Patients!$BL$6:$BL$205),"") | C28: =COUNT(Patients!$BL$6:$BL$205) | D28: 14 יום — היעד האוסטרלי (Cook 2022).
A29: ייעוץ ← ביופסיה | B29: =IFERROR(MEDIAN(Patients!$BM$6:$BM$205),"") | C29: =COUNT(Patients!$BM$6:$BM$205)
A30: ביופסיה ← דוח פתולוגיה | B30: =IFERROR(MEDIAN(Patients!$BN$6:$BN$205),"") | C30: =COUNT(Patients!$BN$6:$BN$205) | D30: Sethi 2022 — ממוצע 4 ימים.
A31: פתולוגיה ← ועדה | B31: =IFERROR(MEDIAN(Patients!$BO$6:$BO$205),"") | C31: =COUNT(Patients!$BO$6:$BO$205)
A32: ייעוץ ← ועדה | B32: =IFERROR(MEDIAN(Patients!$BP$6:$BP$205),"") | C32: =COUNT(Patients!$BP$6:$BP$205) | D32: 14 יום — היעד האוסטרלי.
A33: החלטת ועדה ← טיפול | B33: =IFERROR(MEDIAN(Patients!$BQ$6:$BQ$205),"") | C33: =COUNT(Patients!$BQ$6:$BQ$205) | D33: 28 יום — Cook 2022; 67% עמדו בו.
A34: החלטה ← ניתוח | B34: =IFERROR(MEDIAN(Patients!$BV$6:$BV$205),"") | C34: =COUNT(Patients!$BV$6:$BV$205) | D34: 30 יום — הקריאה הקלינית של חוזר 1/2020.
A35: ייעוץ ← טיפול (CPI) | B35: =IFERROR(MEDIAN(Patients!$BT$6:$BT$205),"") | C35: =COUNT(Patients!$BT$6:$BT$205) | D35: 30 יום — התקן ההולנדי; Schoonbeek 2021 מדד חציון 39.
A36: הפניה ← טיפול | B36: =IFERROR(MEDIAN(Patients!$BU$6:$BU$205),"") | C36: =COUNT(Patients!$BU$6:$BU$205) | D36: 56 יום אוסטרליה · 62 יום NHS.
A37: ניתוח ← הקרנות משלימות | B37: =IFERROR(MEDIAN(Patients!$BW$6:$BW$205),"") | C37: =COUNT(Patients!$BW$6:$BW$205) | D37: 42 יום — NCCN v1.2026, קטגוריה 2A.
A38: ניתוח ← סיום הקרנות (זמן חבילה) | B38: =IFERROR(MEDIAN(Patients!$BX$6:$BX$205),"") | C38: =COUNT(Patients!$BX$6:$BX$205) | D38: 100 יום — Rosenthal 2002.
A39: עמידה ביעדים | B39: שיעור | C39: n
A40: ייעוץ ← טיפול ≤ 30 יום | B40: =IFERROR(AVERAGE(Patients!$CD$6:$CD$205),"") | C40: =SUM(Patients!$CD$6:$CD$205) | D40: התקן ההולנדי דורש 80%.
A41: החלטה ← טיפול ≤ 28 יום | B41: =IFERROR(AVERAGE(Patients!$CE$6:$CE$205),"") | C41: =SUM(Patients!$CE$6:$CE$205) | D41: Cook 2022 — 67% במחקר האוסטרלי.
...

Sheet Patients
A1: מחקר רטרוספקטיבי — מאבחנה לטיפול ראשוני · מחלקת אא״ג וכירורגיית ראש-צוואר, מרכז רפואי מאיר | J1: צהוב = להזנה · אפור = מחושב · כחול = שורת דוגמה סינתטית (שורה 5, אינה נספרת)
A2: זיהוי | H2: דמוגרפיה | U2: גידול | AG2: מסלול | AU2: תאריכים | BL2: מרווחים (ימים) | BZ2: ספי סף | CK2: הערות
A3: מספר מחקר | B3: מספר רץ | C3: קוד אתר | D3: צד | E3: שנת אבחנה | F3: נכלל בניתוח | G3: סיבת הוצאה | H3: גיל באבחנה | I3: מין | J3: ECOG | K3: עישון | L3: שנות קופסה | M3: אלכוהול | N3: ACE-27 | O3: Charlson-Deyo | P3: BMI | Q3: מרחק מגורים | R3: שפת תקשורת | S3: אשכול חברתי-כלכלי ביישוב | T3: ביטוח משלים | U3: היסטולוגיה | V3: cT | W3: cN | X3: cM | Y3: שלב קליני | Z3: מחלה מתקדמת (III–IV) | AA3: p16 / HPV | AB3: EBV | AC3: pT | AD3: pN | AE3: שוליים חיוביים | AF3: חדירה מחוץ לקופסית (ENE) | AG3: מקור ההפניה | AH3: ביופסיה בוצעה מחוץ למרכז | AI3: הדמיה זמינה בייעוץ הראשון | AJ3: אבחנה תחת הרדמה כללית | AK3: מספר חשיפות להרדמה עד הטיפול | AL3: נדרש PET-CT | AM3: נדרשה הערכה דנטלית | AN3: נדרש PEG מניעתי | AO3: ממצא אקראי משמעותי בהדמיה | AP3: מספר הצגות בוועדה | AQ3: עיכוב מיוזמת המטופל | AR3: סיבוך ניתוחי שעיכב טיפול משלים | AS3: הסיבה הראשית לעיכוב | AT3: סיווג מקור העיכוב | AU3: קבלת ההפניה | AV3: ייעוץ ראשון אא״ג | AW3: ביופסיה | AX3: דוח פתולוגיה ממאירה (t₀) | AY3: השלמת הדמיית שלב | AZ3: PET-CT | BA3: הצגה ראשונה בוועדה | BB3: החלטת ועדה סופית | BC3: הודעה למוקד ההסדרים | BD3: תחילת הטיפול המכריע | BE3: מודאליות הטיפול | BF3: אתר הטיפול | BG3: ניתוח | BH3: תחילת הקרנות משלימות | BI3: סיום הטיפול המכריע | BJ3: מצב במועד המעקב | BK3: מעקב אחרון / פטירה | BL3: הפניה ← ייעוץ | BM3: ייעוץ ← ביופסיה | BN3: ביופסיה ← דוח פתולוגיה | BO3: פתולוגיה ← ועדה | BP3: ייעוץ ← ועדה | BQ3: החלטה ← טיפול | BR3: אבחנה ← טיפול · תוצא ראשוני | BS3: ביופסיה ← טיפול | BT3: ייעוץ ← טיפול (CPI) | BU3: הפניה ← טיפול | BV3: החלטה ← ניתוח | BW3: ניתוח ← הקרנות משלימות | BX3: ניתוח ← סיום הקרנות | BY3: הישרדות מאבחנה (חודשים) | BZ3: DTI ≤ 30 יום | CA3: DTI > 40.5 יום | CB3: DTI > 60 יום | CC3: DTI > 67 יום | CD3: CPI ≤ 30 יום | CE3: החלטה ← טיפול ≤ 28 יום | CF3: החלטה ← ניתוח ≤ 30 יום | CG3: הפניה ← טיפול ≤ 56 יום | CH3: ניתוח ← הקרנות ≤ 42 יום | CI3: זמן חבילה ≤ 100 יום | CJ3: אירועי עיכוב מתועדים | CK3: הערות (ללא פרטים מזהים)
A4: id | B4: seq | C4: site | D4: side | E4: yr | F4: incl | G4: exr | H4: age | I4: sex | J4: ecog | K4: smoke | L4: py | M4: alc | N4: ace | O4: cci | P4: bmi | Q4: dist | R4: lang | S4: ses | T4: insur | U4: hist | V4: cT | W4: cN | X4: cM | Y4: stage | Z4: adv | AA4: p16 | AB4: ebv | AC4: pT | AD4: pN | AE4: marg | AF4: ene | AG4: refsrc | AH4: extbx | AI4: imgat1 | AJ4: gabx | AK4: nga | AL4: pet | AM4: dental | AN4: peg | AO4: incid | AP4: nmdt | AQ4: ptdel | AR4: compl | AS4: dmain | AT4: dsrc | AU4: t_ref | AV4: t_v1 | AW4: t_bx | AX4: t_path | AY4: t_img | AZ4: t_pet | BA4: t_mdt | BB4: t_dec | BC4: t_not | BD4: t_tx | BE4: amod | BF4: txsite | BG4: t_surg | BH4: t_port | BI4: t_end | BJ4: vital | BK4: t_lfu | BL4: i_rv | BM4: i_vb | BN4: i_bp | BO4: i_pm | BP4: i_vm | BQ4: i_dt | BR4: i_dti | BS4: i_bti | BT4: i_cpi | BU4: i_rt | BV4: i_ds | BW4: i_sp | BX4: i_pkg | BY4: os | BZ4: f30 | CA4: f40 | CB4: f60 | CC4: f67 | CD4: fcpi | CE4: f28 | CF4: f30s | CG4: f56 | CH4: f42 | CI4: f100 | CJ4: ndel | CK4: note
A5: =IF(OR(B5="",C5="",D5="",AX5=""),"","RET-"&RIGHT(YEAR(AX5),2)&"-"&TEXT(B5,"000")&"-"&C5&"-"&D5&"-"&TEXT(MONTH(AX5),"00")) | B5: 0 | C5: GLT | D5: L | E5: =IF(AX5="","",YEAR(AX5)) | F5: כן | H5: 67 | I5: ז | J5: 1 | K5: מעשן כיום | L5: 45 | M5: מתון | N5: 2 — בינוני | O5: 2 | P5: 23.4 | Q5: 10–30 ק״מ | R5: עברית | S5: 4–6 (בינוני) | T5: מושלם זהב | U5: SCC | V5: T3 | W5: N2b | X5: M0 | Y5: IVA | Z5: =IF(Y5="","",IF(OR(Y5="III",Y5="IV",Y5="IVA",Y5="IVB",Y5="IVC"),1,0)) | AA5: לא רלוונטי | AB5: לא רלוונטי | AC5: T3 | AD5: N2b | AE5: לא | AF5: כן | AG5: אא״ג בקהילה | AH5: לא | AI5: לא | AJ5: כן | AK5: 2 | AL5: כן | AM5: כן | AN5: לא | AO5: לא | AP5: 2 | AQ5: לא | AR5: לא | AS5: תור לסימולציה / הקרנות | AT5: מערכתי — קיבולת | AU5: 44963 | AV5: 44977 | AW5: 44986 | AX5: 44992 | AY5: 44999 | AZ5: 45008 | BA5: 45013 | BB5: 45013 | BD5: 45033 | BE5: ניתוח | BF5: מאיר | BG5: 45033 | BH5: 45071 | BI5: 45117 | BJ5: בחיים | BK5: 46203 | BL5: =IF(OR(AU5="",AV5=""),"",AV5-AU5) | BM5: =IF(OR(AV5="",AW5=""),"",AW5-AV5) | BN5: =IF(OR(AW5="",AX5=""),"",AX5-AW5) | BO5: =IF(OR(AX5="",BA5=""),"",BA5-AX5) | BP5: =IF(OR(AV5="",BA5=""),"",BA5-AV5) | BQ5: =IF(OR(BB5="",BD5=""),"",BD5-BB5) | BR5: =IF(OR(AX5="",BD5=""),"",BD5-AX5) | BS5: =IF(OR(AW5="",BD5=""),"",BD5-AW5) | BT5: =IF(OR(AV5="",BD5=""),"",BD5-AV5) | BU5: =IF(OR(AU5="",BD5=""),"",BD5-AU5) | BV5: =IF(OR(BB5="",BG5=""),"",BG5-BB5) | BW5: =IF(OR(BG5="",BH5=""),"",BH5-BG5) | BX5: =IF(OR(BG5="",BI5=""),"",BI5-BG5) | BY5: =IF(OR(AX5="",BK5=""),"",ROUND((BK5-AX5)/30.44,1)) | BZ5: =IF(BR5="","",IF(BR5<=30,1,0)) | CA5: =IF(BR5="","",IF(BR5>40.5,1,0)) | CB5: =IF(BR5="","",IF(BR5>60,1,0)) | CC5: =IF(BR5="","",IF(BR5>67,1,0)) | CD5: =IF(BT5="","",IF(BT5<=30,1,0)) | CE5: =IF(BQ5="","",IF(BQ5<=28,1,0)) | CF5: =IF(OR(BV5="",BE5<>"ניתוח"),"",IF(BV5<=30,1,0)) | CG5: =IF(BU5="","",IF(BU5<=56,1,0)) | CH5: =IF(BW5="","",IF(BW5<=42,1,0)) | CI5: =IF(BX5="","",IF(BX5<=100,1,0)) | CJ5: =IF(A5="","",COUNTIF(Delays!$B$5:$B$404,A5)) | CK5: שורת דוגמה סינתטית — אינה נתון אמיתי
A6: =IF(OR(B6="",C6="",D6="",AX6=""),"","RET-"&RIGHT(YEAR(AX6),2)&"-"&TEXT(B6,"000")&"-"&C6&"-"&D6&"-"&TEXT(MONTH(AX6),"00")) | B6: 1 | E6: =IF(AX6="","",YEAR(AX6)) | Z6: =IF(Y6="","",IF(OR(Y6="III",Y6="IV",Y6="IVA",Y6="IVB",Y6="IVC"),1,0)) | BL6: =IF(OR(AU6="",AV6=""),"",AV6-AU6) | BM6: =IF(OR(AV6="",AW6=""),"",AW6-AV6) | BN6: =IF(OR(AW6="",AX6=""),"",AX6-AW6) | BO6: =IF(OR(AX6="",BA6=""),"",BA6-AX6) | BP6: =IF(OR(AV6="",BA6=""),"",BA6-AV6) | BQ6: =IF(OR(BB6="",BD6=""),"",BD6-BB6) | BR6: =IF(OR(AX6="",BD6=""),"",BD6-AX6) | BS6: =IF(OR(AW6="",BD6=""),"",BD6-AW6) | BT6: =IF(OR(AV6="",BD6=""),"",BD6-AV6) | BU6: =IF(OR(AU6="",BD6=""),"",BD6-AU6) | BV6: =IF(OR(BB6="",BG6=""),"",BG6-BB6) | BW6: =IF(OR(BG6="",BH6=""),"",BH6-BG6) | BX6: =IF(OR(BG6="",BI6=""),"",BI6-BG6) | BY6: =IF(OR(AX6="",BK6=""),"",ROUND((BK6-AX6)/30.44,1)) | BZ6: =IF(BR6="","",IF(BR6<=30,1,0)) | CA6: =IF(BR6="","",IF(BR6>40.5,1,0)) | CB6: =IF(BR6="","",IF(BR6>60,1,0)) | CC6: =IF(BR6="","",IF(BR6>67,1,0)) | CD6: =IF(BT6="","",IF(BT6<=30,1,0)) | CE6: =IF(BQ6="","",IF(BQ6<=28,1,0)) | CF6: =IF(OR(BV6="",BE6<>"ניתוח"),"",IF(BV6<=30,1,0)) | CG6: =IF(BU6="","",IF(BU6<=56,1,0)) | CH6: =IF(BW6="","",IF(BW6<=42,1,0)) | CI6: =IF(BX6="","",IF(BX6<=100,1,0)) | CJ6: =IF(A6="","",COUNTIF(Delays!$B$5:$B$404,A6))
A7: =IF(OR(B7="",C7="",D7="",AX7=""),"","RET-"&RIGHT(YEAR(AX7),2)&"-"&TEXT(B7,"000")&"-"&C7&"-"&D7&"-"&TEXT(MONTH(AX7),"00")) | B7: 2 | E7: =IF(AX7="","",YEAR(AX7)) | Z7: =IF(Y7="","",IF(OR(Y7="III",Y7="IV",Y7="IVA",Y7="IVB",Y7="IVC"),1,0)) | BL7: =IF(OR(AU7="",AV7=""),"",AV7-AU7) | BM7: =IF(OR(AV7="",AW7=""),"",AW7-AV7) | BN7: =IF(OR(AW7="",AX7=""),"",AX7-AW7) | BO7: =IF(OR(AX7="",BA7=""),"",BA7-AX7) | BP7: =IF(OR(AV7="",BA7=""),"",BA7-AV7) | BQ7: =IF(OR(BB7="",BD7=""),"",BD7-BB7) | BR7: =IF(OR(AX7="",BD7=""),"",BD7-AX7) | BS7: =IF(OR(AW7="",BD7=""),"",BD7-AW7) | BT7: =IF(OR(AV7="",BD7=""),"",BD7-AV7) | BU7: =IF(OR(AU7="",BD7=""),"",BD7-AU7) | BV7: =IF(OR(BB7="",BG7=""),"",BG7-BB7) | BW7: =IF(OR(BG7="",BH7=""),"",BH7-BG7) | BX7: =IF(OR(BG7="",BI7=""),"",BI7-BG7) | BY7: =IF(OR(AX7="",BK7=""),"",ROUND((BK7-AX7)/30.44,1)) | BZ7: =IF(BR7="","",IF(BR7<=30,1,0)) | CA7: =IF(BR7="","",IF(BR7>40.5,1,0)) | CB7: =IF(BR7="","",IF(BR7>60,1,0)) | CC7: =IF(BR7="","",IF(BR7>67,1,0)) | CD7: =IF(BT7="","",IF(BT7<=30,1,0)) | CE7: =IF(BQ7="","",IF(BQ7<=28,1,0)) | CF7: =IF(OR(BV7="",BE7<>"ניתוח"),"",IF(BV7<=30,1,0)) | CG7: =IF(BU7="","",IF(BU7<=56,1,0)) | CH7: =IF(BW7="","",IF(BW7<=42,1,0)) | CI7: =IF(BX7="","",IF(BX7<=100,1,0)) | CJ7: =IF(A7="","",COUNTIF(Delays!$B$5:$B$404,A7))
A8: =IF(OR(B8="",C8="",D8="",AX8=""),"","RET-"&RIGHT(YEAR(AX8),2)&"-"&TEXT(B8,"000")&"-"&C8&"-"&D8&"-"&TEXT(MONTH(AX8),"00")) | B8: 3 | E8: =IF(AX8="","",YEAR(AX8)) | Z8: =IF(Y8="","",IF(OR(Y8="III",Y8="IV",Y8="IVA",Y8="IVB",Y8="IVC"),1,0)) | BL8: =IF(OR(AU8="",AV8=""),"",AV8-AU8) | BM8: =IF(OR(AV8="",AW8=""),"",AW8-AV8) | BN8: =IF(OR(AW8="",AX8=""),"",AX8-AW8) | BO8: =IF(OR(AX8="",BA8=""),"",BA8-AX8) | BP8: =IF(OR(AV8="",BA8=""),"",BA8-AV8) | BQ8: =IF(OR(BB8="",BD8=""),"",BD8-BB8) | BR8: =IF(OR(AX8="",BD8=""),"",BD8-AX8) | BS8: =IF(OR(AW8="",BD8=""),"",BD8-AW8) | BT8: =IF(OR(AV8="",BD8=""),"",BD8-AV8) | BU8: =IF(OR(AU8="",BD8=""),"",BD8-AU8) | BV8: =IF(OR(BB8="",BG8=""),"",BG8-BB8) | BW8: =IF(OR(BG8="",BH8=""),"",BH8-BG8) | BX8: =IF(OR(BG8="",BI8=""),"",BI8-BG8) | BY8: =IF(OR(AX8="",BK8=""),"",ROUND((BK8-AX8)/30.44,1)) | BZ8: =IF(BR8="","",IF(BR8<=30,1,0)) | CA8: =IF(BR8="","",IF(BR8>40.5,1,0)) | CB8: =IF(BR8="","",IF(BR8>60,1,0)) | CC8: =IF(BR8="","",IF(BR8>67,1,0)) | CD8: =IF(BT8="","",IF(BT8<=30,1,0)) | CE8: =IF(BQ8="","",IF(BQ8<=28,1,0)) | CF8: =IF(OR(BV8="",BE8<>"ניתוח"),"",IF(BV8<=30,1,0)) | CG8: =IF(BU8="","",IF(BU8<=56,1,0)) | CH8: =IF(BW8="","",IF(BW8<=42,1,0)) | CI8: =IF(BX8="","",IF(BX8<=100,1,0)) | CJ8: =IF(A8="","",COUNTIF(Delays!$B$5:$B$404,A8))
A9: =IF(OR(B9="",C9="",D9="",AX9=""),"","RET-"&RIGHT(YEAR(AX9),2)&"-"&TEXT(B9,"000")&"-"&C9&"-"&D9&"-"&TEXT(MONTH(AX9),"00")) | B9: 4 | E9: =IF(AX9="","",YEAR(AX9)) | Z9: =IF(Y9="","",IF(OR(Y9="III",Y9="IV",Y9="IVA",Y9="IVB",Y9="IVC"),1,0)) | BL9: =IF(OR(AU9="",AV9=""),"",AV9-AU9) | BM9: =IF(OR(AV9="",AW9=""),"",AW9-AV9) | BN9: =IF(OR(AW9="",AX9=""),"",AX9-AW9) | BO9: =IF(OR(AX9="",BA9=""),"",BA9-AX9) | BP9: =IF(OR(AV9="",BA9=""),"",BA9-AV9) | BQ9: =IF(OR(BB9="",BD9=""),"",BD9-BB9) | BR9: =IF(OR(AX9="",BD9=""),"",BD9-AX9) | BS9: =IF(OR(AW9="",BD9=""),"",BD9-AW9) | BT9: =IF(OR(AV9="",BD9=""),"",BD9-AV9) | BU9: =IF(OR(AU9="",BD9=""),"",BD9-AU9) | BV9: =IF(OR(BB9="",BG9=""),"",BG9-BB9) | BW9: =IF(OR(BG9="",BH9=""),"",BH9-BG9) | BX9: =IF(OR(BG9="",BI9=""),"",BI9-BG9) | BY9: =IF(OR(AX9="",BK9=""),"",ROUND((BK9-AX9)/30.44,1)) | BZ9: =IF(BR9="","",IF(BR9<=30,1,0)) | CA9: =IF(BR9="","",IF(BR9>40.5,1,0)) | CB9: =IF(BR9="","",IF(BR9>60,1,0)) | CC9: =IF(BR9="","",IF(BR9>67,1,0)) | CD9: =IF(BT9="","",IF(BT9<=30,1,0)) | CE9: =IF(BQ9="","",IF(BQ9<=28,1,0)) | CF9: =IF(OR(BV9="",BE9<>"ניתוח"),"",IF(BV9<=30,1,0)) | CG9: =IF(BU9="","",IF(BU9<=56,1,0)) | CH9: =IF(BW9="","",IF(BW9<=42,1,0)) | CI9: =IF(BX9="","",IF(BX9<=100,1,0)) | CJ9: =IF(A9="","",COUNTIF(Delays!$B$5:$B$404,A9))
A10: =IF(OR(B10="",C10="",D10="",AX10=""),"","RET-"&RIGHT(YEAR(AX10),2)&"-"&TEXT(B10,"000")&"-"&C10&"-"&D10&"-"&TEXT(MONTH(AX10),"00")) | B10: 5 | E10: =IF(AX10="","",YEAR(AX10)) | Z10: =IF(Y10="","",IF(OR(Y10="III",Y10="IV",Y10="IVA",Y10="IVB",Y10="IVC"),1,0)) | BL10: =IF(OR(AU10="",AV10=""),"",AV10-AU10) | BM10: =IF(OR(AV10="",AW10=""),"",AW10-AV10) | BN10: =IF(OR(AW10="",AX10=""),"",AX10-AW10) | BO10: =IF(OR(AX10="",BA10=""),"",BA10-AX10) | BP10: =IF(OR(AV10="",BA10=""),"",BA10-AV10) | BQ10: =IF(OR(BB10="",BD10=""),"",BD10-BB10) | BR10: =IF(OR(AX10="",BD10=""),"",BD10-AX10) | BS10: =IF(OR(AW10="",BD10=""),"",BD10-AW10) | BT10: =IF(OR(AV10="",BD10=""),"",BD10-AV10) | BU10: =IF(OR(AU10="",BD10=""),"",BD10-AU10) | BV10: =IF(OR(BB10="",BG10=""),"",BG10-BB10) | BW10: =IF(OR(BG10="",BH10=""),"",BH10-BG10) | BX10: =IF(OR(BG10="",BI10=""),"",BI10-BG10) | BY10: =IF(OR(AX10="",BK10=""),"",ROUND((BK10-AX10)/30.44,1)) | BZ10: =IF(BR10="","",IF(BR10<=30,1,0)) | CA10: =IF(BR10="","",IF(BR10>40.5,1,0)) | CB10: =IF(BR10="","",IF(BR10>60,1,0)) | CC10: =IF(BR10="","",IF(BR10>67,1,0)) | CD10: =IF(BT10="","",IF(BT10<=30,1,0)) | CE10: =IF(BQ10="","",IF(BQ10<=28,1,0)) | CF10: =IF(OR(BV10="",BE10<>"ניתוח"),"",IF(BV10<=30,1,0)) | CG10: =IF(BU10="","",IF(BU10<=56,1,0)) | CH10: =IF(BW10="","",IF(BW10<=42,1,0)) | CI10: =IF(BX10="","",IF(BX10<=100,1,0)) | CJ10: =IF(A10="","",COUNTIF(Delays!$B$5:$B$404,A10))
A11: =IF(OR(B11="",C11="",D11="",AX11=""),"","RET-"&RIGHT(YEAR(AX11),2)&"-"&TEXT(B11,"000")&"-"&C11&"-"&D11&"-"&TEXT(MONTH(AX11),"00")) | B11: 6 | E11: =IF(AX11="","",YEAR(AX11)) | Z11: =IF(Y11="","",IF(OR(Y11="III",Y11="IV",Y11="IVA",Y11="IVB",Y11="IVC"),1,0)) | BL11: =IF(OR(AU11="",AV11=""),"",AV11-AU11) | BM11: =IF(OR(AV11="",AW11=""),"",AW11-AV11) | BN11: =IF(OR(AW11="",AX11=""),"",AX11-AW11) | BO11: =IF(OR(AX11="",BA11=""),"",BA11-AX11) | BP11: =IF(OR(AV11="",BA11=""),"",BA11-AV11) | BQ11: =IF(OR(BB11="",BD11=""),"",BD11-BB11) | BR11: =IF(OR(AX11="",BD11=""),"",BD11-AX11) | BS11: =IF(OR(AW11="",BD11=""),"",BD11-AW11) | BT11: =IF(OR(AV11="",BD11=""),"",BD11-AV11) | BU11: =IF(OR(AU11="",BD11=""),"",BD11-AU11) | BV11: =IF(OR(BB11="",BG11=""),"",BG11-BB11) | BW11: =IF(OR(BG11="",BH11=""),"",BH11-BG11) | BX11: =IF(OR(BG11="",BI11=""),"",BI11-BG11) | BY11: =IF(OR(AX11="",BK11=""),"",ROUND((BK11-AX11)/30.44,1)) | BZ11: =IF(BR11="","",IF(BR11<=30,1,0)) | CA11: =IF(BR11="","",IF(BR11>40.5,1,0)) | CB11: =IF(BR11="","",IF(BR11>60,1,0)) | CC11: =IF(BR11="","",IF(BR11>67,1,0)) | CD11: =IF(BT11="","",IF(BT11<=30,1,0)) | CE11: =IF(BQ11="","",IF(BQ11<=28,1,0)) | CF11: =IF(OR(BV11="",BE11<>"ניתוח"),"",IF(BV11<=30,1,0)) | CG11: =IF(BU11="","",IF(BU11<=56,1,0)) | CH11: =IF(BW11="","",IF(BW11<=42,1,0)) | CI11: =IF(BX11="","",IF(BX11<=100,1,0)) | CJ11: =IF(A11="","",COUNTIF(Delays!$B$5:$B$404,A11))
A12: =IF(OR(B12="",C12="",D12="",AX12=""),"","RET-"&RIGHT(YEAR(AX12),2)&"-"&TEXT(B12,"000")&"-"&C12&"-"&D12&"-"&TEXT(MONTH(AX12),"00")) | B12: 7 | E12: =IF(AX12="","",YEAR(AX12)) | Z12: =IF(Y12="","",IF(OR(Y12="III",Y12="IV",Y12="IVA",Y12="IVB",Y12="IVC"),1,0)) | BL12: =IF(OR(AU12="",AV12=""),"",AV12-AU12) | BM12: =IF(OR(AV12="",AW12=""),"",AW12-AV12) | BN12: =IF(OR(AW12="",AX12=""),"",AX12-AW12) | BO12: =IF(OR(AX12="",BA12=""),"",BA12-AX12) | BP12: =IF(OR(AV12="",BA12=""),"",BA12-AV12) | BQ12: =IF(OR(BB12="",BD12=""),"",BD12-BB12) | BR12: =IF(OR(AX12="",BD12=""),"",BD12-AX12) | BS12: =IF(OR(AW12="",BD12=""),"",BD12-AW12) | BT12: =IF(OR(AV12="",BD12=""),"",BD12-AV12) | BU12: =IF(OR(AU12="",BD12=""),"",BD12-AU12) | BV12: =IF(OR(BB12="",BG12=""),"",BG12-BB12) | BW12: =IF(OR(BG12="",BH12=""),"",BH12-BG12) | BX12: =IF(OR(BG12="",BI12=""),"",BI12-BG12) | BY12: =IF(OR(AX12="",BK12=""),"",ROUND((BK12-AX12)/30.44,1)) | BZ12: =IF(BR12="","",IF(BR12<=30,1,0)) | CA12: =IF(BR12="","",IF(BR12>40.5,1,0)) | CB12: =IF(BR12="","",IF(BR12>60,1,0)) | CC12: =IF(BR12="","",IF(BR12>67,1,0)) | CD12: =IF(BT12="","",IF(BT12<=30,1,0)) | CE12: =IF(BQ12="","",IF(BQ12<=28,1,0)) | CF12: =IF(OR(BV12="",BE12<>"ניתוח"),"",IF(BV12<=30,1,0)) | CG12: =IF(BU12="","",IF(BU12<=56,1,0)) | CH12: =IF(BW12="","",IF(BW12<=42,1,0)) | CI12: =IF(BX12="","",IF(BX12<=100,1,0)) | CJ12: =IF(A12="","",COUNTIF(Delays!$B$5:$B$404,A12))
A13: =IF(OR(B13="",C13="",D13="",AX13=""),"","RET-"&RIGHT(YEAR(AX13),2)&"-"&TEXT(B13,"000")&"-"&C13&"-"&D13&"-"&TEXT(MONTH(AX13),"00")) | B13: 8 | E13: =IF(AX13="","",YEAR(AX13)) | Z13: =IF(Y13="","",IF(OR(Y13="III",Y13="IV",Y13="IVA",Y13="IVB",Y13="IVC"),1,0)) | BL13: =IF(OR(AU13="",AV13=""),"",AV13-AU13) | BM13: =IF(OR(AV13="",AW13=""),"",AW13-AV13) | BN13: =IF(OR(AW13="",AX13=""),"",AX13-AW13) | BO13: =IF(OR(AX13="",BA13=""),"",BA13-AX13) | BP13: =IF(OR(AV13="",BA13=""),"",BA13-AV13) | BQ13: =IF(OR(BB13="",BD13=""),"",BD13-BB13) | BR13: =IF(OR(AX13="",BD13=""),"",BD13-AX13) | BS13: =IF(OR(AW13="",BD13=""),"",BD13-AW13) | BT13: =IF(OR(AV13="",BD13=""),"",BD13-AV13) | BU13: =IF(OR(AU13="",BD13=""),"",BD13-AU13) | BV13: =IF(OR(BB13="",BG13=""),"",BG13-BB13) | BW13: =IF(OR(BG13="",BH13=""),"",BH13-BG13) | BX13: =IF(OR(BG13="",BI13=""),"",BI13-BG13) | BY13: =IF(OR(AX13="",BK13=""),"",ROUND((BK13-AX13)/30.44,1)) | BZ13: =IF(BR13="","",IF(BR13<=30,1,0)) | CA13: =IF(BR13="","",IF(BR13>40.5,1,0)) | CB13: =IF(BR13="","",IF(BR13>60,1,0)) | CC13: =IF(BR13="","",IF(BR13>67,1,0)) | CD13: =IF(BT13="","",IF(BT13<=30,1,0)) | CE13: =IF(BQ13="","",IF(BQ13<=28,1,0)) | CF13: =IF(OR(BV13="",BE13<>"ניתוח"),"",IF(BV13<=30,1,0)) | CG13: =IF(BU13="","",IF(BU13<=56,1,0)) | CH13: =IF(BW13="","",IF(BW13<=42,1,0)) | CI13: =IF(BX13="","",IF(BX13<=100,1,0)) | CJ13: =IF(A13="","",COUNTIF(Delays!$B$5:$B$404,A13))
A14: =IF(OR(B14="",C14="",D14="",AX14=""),"","RET-"&RIGHT(YEAR(AX14),2)&"-"&TEXT(B14,"000")&"-"&C14&"-"&D14&"-"&TEXT(MONTH(AX14),"00")) | B14: 9 | E14: =IF(AX14="","",YEAR(AX14)) | Z14: =IF(Y14="","",IF(OR(Y14="III",Y14="IV",Y14="IVA",Y14="IVB",Y14="IVC"),1,0)) | BL14: =IF(OR(AU14="",AV14=""),"",AV14-AU14) | BM14: =IF(OR(AV14="",AW14=""),"",AW14-AV14) | BN14: =IF(OR(AW14="",AX14=""),"",AX14-AW14) | BO14: =IF(OR(AX14="",BA14=""),"",BA14-AX14) | BP14: =IF(OR(AV14="",BA14=""),"",BA14-AV14) | BQ14: =IF(OR(BB14="",BD14=""),"",BD14-BB14) | BR14: =IF(OR(AX14="",BD14=""),"",BD14-AX14) | BS14: =IF(OR(AW14="",BD14=""),"",BD14-AW14) | BT14: =IF(OR(AV14="",BD14=""),"",BD14-AV14) | BU14: =IF(OR(AU14="",BD14=""),"",BD14-AU14) | BV14: =IF(OR(BB14="",BG14=""),"",BG14-BB14) | BW14: =IF(OR(BG14="",BH14=""),"",BH14-BG14) | BX14: =IF(OR(BG14="",BI14=""),"",BI14-BG14) | BY14: =IF(OR(AX14="",BK14=""),"",ROUND((BK14-AX14)/30.44,1)) | BZ14: =IF(BR14="","",IF(BR14<=30,1,0)) | CA14: =IF(BR14="","",IF(BR14>40.5,1,0)) | CB14: =IF(BR14="","",IF(BR14>60,1,0)) | CC14: =IF(BR14="","",IF(BR14>67,1,0)) | CD14: =IF(BT14="","",IF(BT14<=30,1,0)) | CE14: =IF(BQ14="","",IF(BQ14<=28,1,0)) | CF14: =IF(OR(BV14="",BE14<>"ניתוח"),"",IF(BV14<=30,1,0)) | CG14: =IF(BU14="","",IF(BU14<=56,1,0)) | CH14: =IF(BW14="","",IF(BW14<=42,1,0)) | CI14: =IF(BX14="","",IF(BX14<=100,1,0)) | CJ14: =IF(A14="","",COUNTIF(Delays!$B$5:$B$404,A14))
A15: =IF(OR(B15="",C15="",D15="",AX15=""),"","RET-"&RIGHT(YEAR(AX15),2)&"-"&TEXT(B15,"000")&"-"&C15&"-"&D15&"-"&TEXT(MONTH(AX15),"00")) | B15: 10 | E15: =IF(AX15="","",YEAR(AX15)) | Z15: =IF(Y15="","",IF(OR(Y15="III",Y15="IV",Y15="IVA",Y15="IVB",Y15="IVC"),1,0)) | BL15: =IF(OR(AU15="",AV15=""),"",AV15-AU15) | BM15: =IF(OR(AV15="",AW15=""),"",AW15-AV15) | BN15: =IF(OR(AW15="",AX15=""),"",AX15-AW15) | BO15: =IF(OR(AX15="",BA15=""),"",BA15-AX15) | BP15: =IF(OR(AV15="",BA15=""),"",BA15-AV15) | BQ15: =IF(OR(BB15="",BD15=""),"",BD15-BB15) | BR15: =IF(OR(AX15="",BD15=""),"",BD15-AX15) | BS15: =IF(OR(AW15="",BD15=""),"",BD15-AW15) | BT15: =IF(OR(AV15="",BD15=""),"",BD15-AV15) | BU15: =IF(OR(AU15="",BD15=""),"",BD15-AU15) | BV15: =IF(OR(BB15="",BG15=""),"",BG15-BB15) | BW15: =IF(OR(BG15="",BH15=""),"",BH15-BG15) | BX15: =IF(OR(BG15="",BI15=""),"",BI15-BG15) | BY15: =IF(OR(AX15="",BK15=""),"",ROUND((BK15-AX15)/30.44,1)) | BZ15: =IF(BR15="","",IF(BR15<=30,1,0)) | CA15: =IF(BR15="","",IF(BR15>40.5,1,0)) | CB15: =IF(BR15="","",IF(BR15>60,1,0)) | CC15: =IF(BR15="","",IF(BR15>67,1,0)) | CD15: =IF(BT15="","",IF(BT15<=30,1,0)) | CE15: =IF(BQ15="","",IF(BQ15<=28,1,0)) | CF15: =IF(OR(BV15="",BE15<>"ניתוח"),"",IF(BV15<=30,1,0)) | CG15: =IF(BU15="","",IF(BU15<=56,1,0)) | CH15: =IF(BW15="","",IF(BW15<=42,1,0)) | CI15: =IF(BX15="","",IF(BX15<=100,1,0)) | CJ15: =IF(A15="","",COUNTIF(Delays!$B$5:$B$404,A15))
A16: =IF(OR(B16="",C16="",D16="",AX16=""),"","RET-"&RIGHT(YEAR(AX16),2)&"-"&TEXT(B16,"000")&"-"&C16&"-"&D16&"-"&TEXT(MONTH(AX16),"00")) | B16: 11 | E16: =IF(AX16="","",YEAR(AX16)) | Z16: =IF(Y16="","",IF(OR(Y16="III",Y16="IV",Y16="IVA",Y16="IVB",Y16="IVC"),1,0)) | BL16: =IF(OR(AU16="",AV16=""),"",AV16-AU16) | BM16: =IF(OR(AV16="",AW16=""),"",AW16-AV16) | BN16: =IF(OR(AW16="",AX16=""),"",AX16-AW16) | BO16: =IF(OR(AX16="",BA16=""),"",BA16-AX16) | BP16: =IF(OR(AV16="",BA16=""),"",BA16-AV16) | BQ16: =IF(OR(BB16="",BD16=""),"",BD16-BB16) | BR16: =IF(OR(AX16="",BD16=""),"",BD16-AX16) | BS16: =IF(OR(AW16="",BD16=""),"",BD16-AW16) | BT16: =IF(OR(AV16="",BD16=""),"",BD16-AV16) | BU16: =IF(OR(AU16="",BD16=""),"",BD16-AU16) | BV16: =IF(OR(BB16="",BG16=""),"",BG16-BB16) | BW16: =IF(OR(BG16="",BH16=""),"",BH16-BG16) | BX16: =IF(OR(BG16="",BI16=""),"",BI16-BG16) | BY16: =IF(OR(AX16="",BK16=""),"",ROUND((BK16-AX16)/30.44,1)) | BZ16: =IF(BR16="","",IF(BR16<=30,1,0)) | CA16: =IF(BR16="","",IF(BR16>40.5,1,0)) | CB16: =IF(BR16="","",IF(BR16>60,1,0)) | CC16: =IF(BR16="","",IF(BR16>67,1,0)) | CD16: =IF(BT16="","",IF(BT16<=30,1,0)) | CE16: =IF(BQ16="","",IF(BQ16<=28,1,0)) | CF16: =IF(OR(BV16="",BE16<>"ניתוח"),"",IF(BV16<=30,1,0)) | CG16: =IF(BU16="","",IF(BU16<=56,1,0)) | CH16: =IF(BW16="","",IF(BW16<=42,1,0)) | CI16: =IF(BX16="","",IF(BX16<=100,1,0)) | CJ16: =IF(A16="","",COUNTIF(Delays!$B$5:$B$404,A16))
A17: =IF(OR(B17="",C17="",D17="",AX17=""),"","RET-"&RIGHT(YEAR(AX17),2)&"-"&TEXT(B17,"000")&"-"&C17&"-"&D17&"-"&TEXT(MONTH(AX17),"00")) | B17: 12 | E17: =IF(AX17="","",YEAR(AX17)) | Z17: =IF(Y17="","",IF(OR(Y17="III",Y17="IV",Y17="IVA",Y17="IVB",Y17="IVC"),1,0)) | BL17: =IF(OR(AU17="",AV17=""),"",AV17-AU17) | BM17: =IF(OR(AV17="",AW17=""),"",AW17-AV17) | BN17: =IF(OR(AW17="",AX17=""),"",AX17-AW17) | BO17: =IF(OR(AX17="",BA17=""),"",BA17-AX17) | BP17: =IF(OR(AV17="",BA17=""),"",BA17-AV17) | BQ17: =IF(OR(BB17="",BD17=""),"",BD17-BB17) | BR17: =IF(OR(AX17="",BD17=""),"",BD17-AX17) | BS17: =IF(OR(AW17="",BD17=""),"",BD17-AW17) | BT17: =IF(OR(AV17="",BD17=""),"",BD17-AV17) | BU17: =IF(OR(AU17="",BD17=""),"",BD17-AU17) | BV17: =IF(OR(BB17="",BG17=""),"",BG17-BB17) | BW17: =IF(OR(BG17="",BH17=""),"",BH17-BG17) | BX17: =IF(OR(BG17="",BI17=""),"",BI17-BG17) | BY17: =IF(OR(AX17="",BK17=""),"",ROUND((BK17-AX17)/30.44,1)) | BZ17: =IF(BR17="","",IF(BR17<=30,1,0)) | CA17: =IF(BR17="","",IF(BR17>40.5,1,0)) | CB17: =IF(BR17="","",IF(BR17>60,1,0)) | CC17: =IF(BR17="","",IF(BR17>67,1,0)) | CD17: =IF(BT17="","",IF(BT17<=30,1,0)) | CE17: =IF(BQ17="","",IF(BQ17<=28,1,0)) | CF17: =IF(OR(BV17="",BE17<>"ניתוח"),"",IF(BV17<=30,1,0)) | CG17: =IF(BU17="","",IF(BU17<=56,1,0)) | CH17: =IF(BW17="","",IF(BW17<=42,1,0)) | CI17: =IF(BX17="","",IF(BX17<=100,1,0)) | CJ17: =IF(A17="","",COUNTIF(Delays!$B$5:$B$404,A17))
... A205: =IF(OR(B205="",C205="",D205="",AX205=""),"","RET-"&RIGHT(YEAR(AX205),2)&"-"&TEXT(B205,"000")&"-"&C205&"-"&D205&"-"&TEXT(MONTH(AX205),"00")) | B205: 200 | E205: =IF(AX205="","",YEAR(AX205)) | Z205: =IF(Y205="","",IF(OR(Y205="III",Y205="IV",Y205="IVA",Y205="IVB",Y205="IVC"),1,0)) | BL205: =IF(OR(AU205="",AV205=""),"",AV205-AU205) | BM205: =IF(OR(AV205="",AW205=""),"",AW205-AV205) | BN205: =IF(OR(AW205="",AX205=""),"",AX205-AW205) | BO205: =IF(OR(AX205="",BA205=""),"",BA205-AX205) | BP205: =IF(OR(AV205="",BA205=""),"",BA205-AV205) | BQ205: =IF(OR(BB205="",BD205=""),"",BD205-BB205) | BR205: =IF(OR(AX205="",BD205=""),"",BD205-AX205) | BS205: =IF(OR(AW205="",BD205=""),"",BD205-AW205) | BT205: =IF(OR(AV205="",BD205=""),"",BD205-AV205) | BU205: =IF(OR(AU205="",BD205=""),"",BD205-AU205) | BV205: =IF(OR(BB205="",BG205=""),"",BG205-BB205) | BW205: =IF(OR(BG205="",BH205=""),"",BH205-BG205) | BX205: =IF(OR(BG205="",BI205=""),"",BI205-BG205) | BY205: =IF(OR(AX205="",BK205=""),"",ROUND((BK205-AX205)/30.44,1)) | BZ205: =IF(BR205="","",IF(BR205<=30,1,0)) | CA205: =IF(BR205="","",IF(BR205>40.5,1,0)) | CB205: =IF(BR205="","",IF(BR205>60,1,0)) | CC205: =IF(BR205="","",IF(BR205>67,1,0)) | CD205: =IF(BT205="","",IF(BT205<=30,1,0)) | CE205: =IF(BQ205="","",IF(BQ205<=28,1,0)) | CF205: =IF(OR(BV205="",BE205<>"ניתוח"),"",IF(BV205<=30,1,0)) | CG205: =IF(BU205="","",IF(BU205<=56,1,0)) | CH205: =IF(BW205="","",IF(BW205<=42,1,0)) | CI205: =IF(BX205="","",IF(BX205<=100,1,0)) | CJ205: =IF(A205="","",COUNTIF(Delays!$B$5:$B$404,A205))

Sheet Delays
A1: יומן אירועי עיכוב — אירוע אחד בשורה. מטופל יכול להופיע כמה פעמים.
A3: מס׳ אירוע | B3: מספר מחקר | C3: המקטע | D3: סיבת העיכוב | E3: סיווג המקור | F3: תחילת ההמתנה | G3: סוף ההמתנה | H3: ימים | I3: נמנע לכאורה | J3: הערה (ללא פרטים מזהים)
A4: n | B4: pid | C4: phase | D4: reason | E4: src | F4: start | G4: end | H4: days | I4: avoid | J4: note
A5: D-001 | H5: =IF(OR(F5="",G5=""),"",G5-F5)
A6: D-002 | H6: =IF(OR(F6="",G6=""),"",G6-F6)
A7: D-003 | H7: =IF(OR(F7="",G7=""),"",G7-F7)
A8: D-004 | H8: =IF(OR(F8="",G8=""),"",G8-F8)
A9: D-005 | H9: =IF(OR(F9="",G9=""),"",G9-F9)
A10: D-006 | H10: =IF(OR(F10="",G10=""),"",G10-F10)
A11: D-007 | H11: =IF(OR(F11="",G11=""),"",G11-F11)
A12: D-008 | H12: =IF(OR(F12="",G12=""),"",G12-F12)
A13: D-009 | H13: =IF(OR(F13="",G13=""),"",G13-F13)
A14: D-010 | H14: =IF(OR(F14="",G14=""),"",G14-F14)
A15: D-011 | H15: =IF(OR(F15="",G15=""),"",G15-F15)
A16: D-012 | H16: =IF(OR(F16="",G16=""),"",G16-F16)
... A404: D-400 | H404: =IF(OR(F404="",G404=""),"",G404-F404)

Sheet Parameters
A1: הפרמטרים שנמדדו במחקרים המובילים — ומה נאסף אצלנו
A2: כל שורה: מחקר אחד. כל מספר בטבלה נקרא מהמקור עצמו; היכן שהנתון לא היה בטקסט הנגיש — נכתב ״לא אומת״.
A4: המחקר | B4: שנה | C4: מדינה / מקור נתונים | D4: n | E4: תקופה | F4: עוגן ההתחלה | G4: עוגן הסיום | H4: מקטעי משנה שנמדדו | I4: משתנים מסבירים | J4: תוצאים | K4: סף ושיטת הפקתו | L4: התוצאה המרכזית | M4: ממצאי אפס | N4: מזהה
A5: Amarillo D, et al. | B5: 2024 | C5: אורוגוואי · Hospital de Clínicas, מונטווידאו | D5: 377 | E5: 2005–2015 | F5: אבחנה | G5: תחילת הטיפול | H5: אין — מרווח יחיד | I5: מין · אתר הגידול · שלב (מקומי מול מתקדם) · סוג הטיפול (ניתוח 57.8% / הקרנות 42.2%) | J5: הישרדות כוללת | K5: 40.5 יום · Recursive partitioning | L5: חציון OS‏ 36.16 מול 23.14 חודשים (p=0.006) · מחלה מקומית 116.3 מול 55 (p=0.009) · גרון 70.58 מול 27.75 · חציון המרווח בפועל 32 יום | M5: לא דווחו ממצאי אפס | N5: Am J Otolaryngol Head Neck Surg 2024;7(1) · תקציר כנס: Oral Oncol 2021;118 suppl, doi:10.1016/S1368-8375(21)00499-1
A6: Murphy CT, et al. | B6: 2016 | C6: ארה״ב · NCDB | D6: 51,655 | E6: לא אומת | F6: אבחנה | G6: תחילת טיפול מרפא | H6: אין | I6: לא אומת מהטקסט הנגיש | J6: הישרדות כוללת | K6: 67 יום (וגם 46–52) · RPA עם conditional inference trees, 1,000 חזרות | L6: TTI 61–90 מול <30 יום: HR 1.13 (1.08–1.19) · חציון OS‏ 71.9 / 61 / 46.6 חודשים | M6: — | N6: PMID 26628469 · doi:10.1200/JCO.2015.61.5906
A7: Murphy CT, et al. | B7: 2015 | C7: ארה״ב · NCDB | D7: 274,630 | E7: 1998–2011 | F7: אבחנה | G7: תחילת טיפול מכריע | H7: אין | I7: מודאליות · סוג המוסד (אקדמי) · שלב · שנה · מעבר בין מוסדות אחרי האבחנה | J7: ה-TTI עצמו (מגמה ומנבאים) | K7: אין — רגרסיה שלילית-בינומית מנופחת-אפסים | L7: חציון TTI‏ 26 יום; עלה מ-19 ל-30 יום (p<0.0001) · מוסד אקדמי 33 · מעבר מוסדות 37 · כימו-הקרנות 39 | M7: — | N7: PMID 25490875 · doi:10.1002/cncr.29191
A8: Liao DZ, et al. | B8: 2019 | C8: ארה״ב · Montefiore, ברונקס | D8: 956 | E8: 2005–2017 | F8: אבחנה היסטופתולוגית | G8: תחילת הטיפול | H8: אין | I8: מוצא · ביטוח (Medicaid) · BMI · האם האבחנה נעשתה במוסד אחר · גיל · מין | J8: הישרדות כוללת · הישנות · סיבות העיכוב | K8: >60 יום · Recursive partitioning | L8: חציון TTI‏ 40 יום (IQR 28–56) · מעל 60 יום: HR 1.69 (1.32–2.18) לתמותה, OR 1.77 (1.07–2.93) להישנות | M8: — | N8: PMID 31513264 · doi:10.1001/jamaoto.2019.2414
A9: Tsai WC, et al. | B9: 2017 | C9: טאיוואן · מרשם הסרטן + ביטוח לאומי · חלל הפה בלבד | D9: 21,263 | E9: 2004–2010 | F9: ביופסיה מאשרת | G9: טיפול ראשון (ניתוח / הקרנות / כימו) | H9: אין | I9: מין · גיל · תת-אתר · מחלה קשה נלווית · שלב (AJCC 6/7) · שכר · עיור · מודאליות · דיון רב-תחומי תוך 180 יום · Charlson-Deyo · דרג בית החולים · בעלות · נפח פעילות | J9: הישרדות כוללת | K9: ≤30 / 31–120 / >120 יום · חלוקה מוגדרת מראש | L9: 31–120 יום: aHR 1.18 (1.11–1.25) · >120 יום: aHR 1.32 (1.19–1.47) · דיון רב-תחומי: aHR 0.93 (0.87–0.98) | M9: רמת העיור לא מובהקת ברב-משתני · הדיון הרב-תחומי לא מובהק בחד-משתני | N9: PMID 28388649 · doi:10.1371/journal.pone.0175148
A10: Rygalski CJ, et al. | B10: 2021 | C10: ארה״ב · NCDB · מנותחים בלבד | D10: 37,730 | E10: 2004–2016 | F10: אבחנה | G10: הניתוח המכריע בגידול הראשוני | H10: אין | I10: גיל · מין · מוצא · ביטוח · מגורים עירוניים · סוג מוסד · Charlson-Deyo · הכנסה · השכלה · שוליים · שלב פתולוגי · טיפול משלים · אתר | J10: הישרדות כוללת (מיום הניתוח) | K10: 67 יום · 100 דגימות bootstrap + LOESS + restricted cubic splines | L10: חציון 33 יום (IQR 21–49) · מעל 67 יום: HR 1.189 (1.122–1.261) · ‎+4.6% סיכון לכל 30 יום | M10: חלל הפה מעל 90 יום: HR 1.10 (0.98–1.23) — לא מובהק · גרון/היפופרינקס הקשר החלש ביותר | N10: PMID 33188461 · doi:10.1245/s10434-020-09326-4
A11: Vasudev M, et al. | B11: 2024 | C11: ארה״ב · NCDB · לוע הפה, ניתוח ראשוני | D11: 1,643 חיובי HPV · 391 שלילי | E11: 2010–2017 | F11: אבחנה | G11: תחילת הטיפול | H11: ניתוח ← הקרנות משלימות | I11: מצב HPV · מין · גיל · מוצא · ביטוח · משך ההקרנה · גודל הגידול · פלישה לימפו-וסקולרית · מספר קשריות · גישה רובוטית | J11: הישרדות כוללת | K11: TTI ≤30 / 31–60 / ≥61 · ניתוח←הקרנות ≤42 / 43–66 / ≥67 · חלוקה מוגדרת מראש | L11: שליליי HPV: 43–66 יום HR 1.63 (p=0.049) · ≥67 יום HR 2.10 (p=0.032) · רובוטי בחיוביי HPV HR 0.41 (p<0.001) | M11: בחיוביי HPV העיכוב לא היה מובהק ברב-משתני · מין, גיל, מוצא, ביטוח ומשך ההקרנה — כולם לא מובהקים | N11: PMID 38532532 · doi:10.1002/ohn.699
A12: Guo LF, et al. | B12: 2026 | C12: ארה״ב · SEER · הקרנות מכריעות במחלה מתקדמת | D12: 18,657 | E12: 2005–2015 | F12: אבחנה | G12: תחילת ההקרנות | H12: אין | I12: מין · גיל · שנת אבחנה · כימותרפיה · שלב קליני AJCC · אתר ראשוני. ‎HPV לא היה זמין | J12: הישרדות כוללת · הישרדות ייעודית למחלה | K12: 61 יום · שתי RPA (מתוכן אחת עם 1,000 חלוקות) + penalized spline | L12: חציון 39 יום (IQR 27–55) · מעל 61 יום: CSS HR 1.209 (1.143–1.278), OS HR 1.199 (1.146–1.256) | M12: המרווח כמשתנה רציף — לא מובהק · היפופרינקס 1.015 (0.884–1.166) · קבוצת הביניים ב-OS‏ 0.972 (0.935–1.011) | N12: PMID 42627284 · doi:10.1177/10732748261481970
A13: Schoonbeek RC, et al. | B13: 2021 | C13: הולנד · UMCG, מרכז שלישוני | D13: 192 | E13: 2014–2016 | F13: שני עוגנים: ייעוץ ראשון (CPI) וגם אבחנה היסטולוגית (TTI) | G13: תחילת הטיפול | H13: CPI מול TTI באותה קוהורטה | I13: גיל · מין · עישון · אלכוהול · ACE-27 · ריבוי תרופות · BMI · אתר · היכן נלקחה הביופסיה · דרגה · שלב · מודאליות · שחזור · ניתוח לייזר · והערכה גריאטרית מלאה (MUST, Katz-ADL, IADL, TUG, נפילות, השכלה, מצב משפחתי, MMSE, דליריום, GDS-15, G8, GFI) | J13: שיעור העומדים ב-30 יום | K13: 30 יום · התקן ההולנדי | L13: חציון CPI‏ 39 יום · חציון TTI‏ 40 יום · רק 37% תוך 30 יום · שלב IV: OR 7.97 (1.99–31.97) · הקרנות ראשוניות: OR 9.93 (2.75–35.92) | M13: כל מרכיבי ההערכה הגריאטרית — ללא קשר לעיכוב · שחזור ניתוחי — לא מובהק · בתת-קבוצת ההקרנות אף מנבא לא שרד | N13: PMID 33555121 · doi:10.1111/ecc.13419
A14: Schoonbeek RC, et al. | B14: 2022 | C14: הולנד · שני מרכזים · גיל 60+ | D14: 525 | E14: 2015–2017 | F14: ייעוץ ראשון | G14: תחילת הטיפול | H14: אין | I14: עישון · שלב · מודאליות · גיל · מין | J14: אשפוז מעל 14 יום בשנה הראשונה · הישרדות · הישנות | K14: 30 יום | L14: חציון 34 יום · 36.3% תוך 30 יום · עיכוב ≥30 יום ← אשפוז ממושך OR 4.66 (2.59–8.37) | M14: העיכוב לא נקשר להישרדות כוללת ולא להישנות | N14: PMID 35043734 · doi:10.1177/01945998211072828
A15: Schoonbeek RC, et al. | B15: 2021 | C15: הולנד · UMCG · ממצאים אקראיים בבירור | D15: 592 | E15: 2010–2011 מול 2016–2017 | F15: ייעוץ ראשון | G15: תחילת הטיפול | H15: אין | I15: נוכחות ממצא אקראי משמעותי בהדמיה | J15: עיכוב בתחילת הטיפול · הישרדות | K15: — | L15: ממצא אקראי ב-61.5%; משמעותי ב-128 (21.6%) · ממצא משמעותי — גורם עצמאי לעיכוב | M15: הסיכון המוגבר לתמותה לא היה מובהק: HR 1.46 (p=0.079) | N15: PMID 34030108 · doi:10.1016/j.oraloncology.2021.105350
... A25: Matsumoto K, et al. | B25: 2024 | C25: יפן · מיקום גאוגרפי והקרנות | D25: לא אומת | E25: לא אומת | F25: אבחנה | G25: תחילת הקרנות | H25: אין | I25: מרחק ממרכז ההקרנות · נקודת המגע הראשונה (אא״ג מול אחר) · תקופות סגירה של בית החולים | J25: עיכוב בתחילת ההקרנות | K25: — | L25: סגירת שירות aOR 6.62 · מרחק aOR 7.60 · פנייה ראשונה שאינה לאא״ג aOR 7.27 | M25: — | N25: PMID 39655148 · doi:10.7759/cureus.73253

Sheet Dictionary
A1: גיליון | B1: קוד | C1: שדה | D1: סוג | E1: קבוצה | F1: הגדרה · המחקר שדורש אותו
A2: Patients | B2: id | C2: מספר מחקר | D2: מחושב | E2: זיהוי | F2: נוצר אוטומטית ממספר רץ, אתר, צד ותאריך דוח הפתולוגיה. לאחר ההקצאה — קבוע.
A3: Patients | B3: seq | C3: מספר רץ | D3: מספר | E3: זיהוי | F3: לפי סדר האיתור ברשימת הוועדה.
A4: Patients | B4: site | C4: קוד אתר | D4: רשימה | E4: זיהוי | F4: רשימה בגיליון Lists. נמדד בכל המחקרים.
A5: Patients | B5: side | C5: צד | D5: רשימה | E5: זיהוי | F5: R ימין · L שמאל · M קו אמצע · B דו-צדדי.
A6: Patients | B6: yr | C6: שנת אבחנה | D6: מחושב | E6: זיהוי | F6: לניתוח מגמה — Murphy 2015.
A7: Patients | B7: incl | C7: נכלל בניתוח | D7: רשימה | E7: זיהוי | F7: ״לא״ = הוצא; יש לציין סיבה.
A8: Patients | B8: exr | C8: סיבת הוצאה | D8: רשימה | E8: זיהוי | F8: לתרשים ה-STROBE.
A9: Patients | B9: age | C9: גיל באבחנה | D9: מספר | E9: דמוגרפיה | F9: גיל בלבד — לא תאריך לידה. כל המחקרים.
A10: Patients | B10: sex | C10: מין | D10: רשימה | E10: דמוגרפיה | F10: Amarillo 2024 — מנבא מובהק ברב-משתני.
A11: Patients | B11: ecog | C11: ECOG | D11: רשימה | E11: דמוגרפיה
A12: Patients | B12: smoke | C12: עישון | D12: רשימה | E12: דמוגרפיה | F12: Schoonbeek 2022 — עישון פעיל מנבא עיכוב.
A13: Patients | B13: py | C13: שנות קופסה | D13: מספר | E13: דמוגרפיה
A14: Patients | B14: alc | C14: אלכוהול | D14: רשימה | E14: דמוגרפיה | F14: Schoonbeek 2021.
A15: Patients | B15: ace | C15: ACE-27 | D15: רשימה | E15: דמוגרפיה | F15: מדד התחלואה הנלווית של Schoonbeek.
A16: Patients | B16: cci | C16: Charlson-Deyo | D16: רשימה | E16: דמוגרפיה | F16: מדד התחלואה של Tsai 2017 ו-Rygalski 2021.
A17: Patients | B17: bmi | C17: BMI | D17: מספר | E17: דמוגרפיה | F17: Liao 2019 — BMI<18.5 מנבא עיכוב.
A18: Patients | B18: dist | C18: מרחק מגורים | D18: רשימה | E18: דמוגרפיה | F18: בטווחים בלבד. Matsumoto 2024.
A19: Patients | B19: lang | C19: שפת תקשורת | D19: רשימה | E19: דמוגרפיה | F19: Kwok 2023 — נבדק ונמצא לא מובהק.
A20: Patients | B20: ses | C20: אשכול חברתי-כלכלי ביישוב | D20: רשימה | E20: דמוגרפיה | F20: מקביל להכנסה/השכלה ב-NCDB.
A21: Patients | B21: insur | C21: ביטוח משלים | D21: רשימה | E21: דמוגרפיה | F21: מקביל למשתנה הביטוח ב-Liao 2019.
A22: Patients | B22: hist | C22: היסטולוגיה | D22: רשימה | E22: גידול
A23: Patients | B23: cT | C23: cT | D23: רשימה | E23: גידול | F23: AJCC 8 — לציין מהדורה אם שונה.
A24: Patients | B24: cN | C24: cN | D24: רשימה | E24: גידול | F24: AJCC 8.
A25: Patients | B25: cM | C25: cM | D25: רשימה | E25: גידול | F25: AJCC 8.
A26: Patients | B26: stage | C26: שלב קליני | D26: רשימה | E26: גידול | F26: המנבא החזק ביותר לעיכוב — Schoonbeek 2021 (OR 7.97).
A27: Patients | B27: adv | C27: מחלה מתקדמת (III–IV) | D27: מחושב | E27: גידול | F27: החלוקה של Amarillo 2024.
A28: Patients | B28: p16 | C28: p16 / HPV | D28: רשימה | E28: גידול | F28: Vasudev 2024 — משנה את כיוון ההשפעה.
A29: Patients | B29: ebv | C29: EBV | D29: רשימה | E29: גידול | F29: לוע האף.
A30: Patients | B30: pT | C30: pT | D30: רשימה | E30: גידול | F30: Rygalski 2021 — שלב פתולוגי.
A31: Patients | B31: pN | C31: pN | D31: רשימה | E31: גידול
A32: Patients | B32: marg | C32: שוליים חיוביים | D32: רשימה | E32: גידול | F32: Rygalski 2021.
A33: Patients | B33: ene | C33: חדירה מחוץ לקופסית (ENE) | D33: רשימה | E33: גידול | F33: קובע צורך בהקרנות משלימות.
A34: Patients | B34: refsrc | C34: מקור ההפניה | D34: רשימה | E34: מסלול | F34: Sethi 2022 · Kwok 2023 — הפניה מרופא משפחה מאריכה.
A35: Patients | B35: extbx | C35: ביופסיה בוצעה מחוץ למרכז | D35: רשימה | E35: מסלול | F35: Schoonbeek 2021 — משנה מהותית את ה-TTI.
A36: Patients | B36: imgat1 | C36: הדמיה זמינה בייעוץ הראשון | D36: רשימה | E36: מסלול | F36: Connell 2020 — 43.1 מול 37.4 ימים.
A37: Patients | B37: gabx | C37: אבחנה תחת הרדמה כללית | D37: רשימה | E37: מסלול | F37: Connell 2020.
A38: Patients | B38: nga | C38: מספר חשיפות להרדמה עד הטיפול | D38: מספר | E38: מסלול | F38: Connell 2020 — 64% נזקקו לשתיים.
A39: Patients | B39: pet | C39: נדרש PET-CT | D39: רשימה | E39: מסלול | F39: Cook 2022 — +7.5 ימים.
A40: Patients | B40: dental | C40: נדרשה הערכה דנטלית | D40: רשימה | E40: מסלול | F40: Cook 2022 · van Huizen 2018.
...

Sheet Lists
A1: site | D1: side | G1: hist | I1: T | K1: N | M1: M | O1: stage | Q1: marker | S1: yn | U1: ynu | W1: sex | Y1: ecog | AA1: smoke | AC1: alc | AE1: ace | AG1: cci | AI1: dist | AK1: lang | AM1: ses | AO1: insur | AQ1: refsrc | AS1: mod | AU1: txsite | AW1: dreason | AY1: dphase | BA1: dsrc | BC1: excl | BE1: vital
A2: OT | B2: לשון (חלל הפה) | D2: R | E2: ימין | G2: SCC | I2: TX | K2: NX | M2: M0 | O2: 0 | Q2: חיובי | S2: כן | U2: כן | W2: ז | Y2: 0 | AA2: מעולם לא | AC2: ללא | AE2: 0 — ללא | AG2: 0 | AI2: פחות מ-10 ק״מ | AK2: עברית | AM2: 1–3 (נמוך) | AO2: ללא ביטוח משלים | AQ2: רופא משפחה | AS2: ניתוח | AU2: מאיר | AW2: השלמת פתולוגיה / צביעות | AY2: הפניה ← ייעוץ | BA2: מערכתי — קיבולת | BC2: מתחת לגיל 18 | BE2: בחיים
A3: FOM | B3: רצפת הפה | D3: L | E3: שמאל | G3: SCC — basaloid / variant | I3: T0 | K3: N0 | M3: M1 | O3: I | Q3: שלילי | S3: לא | U3: לא | W3: נ | Y3: 1 | AA3: עישן בעבר | AC3: מתון | AE3: 1 — קל | AG3: 1 | AI3: 10–30 ק״מ | AK3: ערבית | AM3: 4–6 (בינוני) | AO3: מושלם זהב | AQ3: אא״ג בקהילה | AS3: הקרנות | AU3: דוידוף | AW3: חוות דעת פתולוגית שנייה | AY3: ייעוץ ← אבחנה | BA3: מערכתי — תיאום | BC3: הישנות / גידול שני | BE3: נפטר
A4: BUC | B4: רירית הלחי | D4: M | E4: קו אמצע | G4: Nasopharyngeal carcinoma (WHO) | I4: Tis | K4: N1 | O4: II | Q4: לא נבדק | U4: לא מתועד | Y4: 2 | AA4: מעשן כיום | AC4: כבד | AE4: 2 — בינוני | AG4: 2 | AI4: 30–60 ק״מ | AK4: רוסית | AM4: 7–10 (גבוה) | AO4: מושלם פלטינום | AQ4: רופא שיניים / כירורג פה ולסת | AS4: כימו-הקרנות | AU4: אחר בכללית | AW4: השלמת הדמיה | AY4: אבחנה ← ועדה | BA4: קליני מוצדק | BC4: טופל קודם במוסד אחר | BE4: אבד למעקב
A5: GUM | B5: חניכיים / רכס מכתשי | D5: B | E5: דו-צדדי | G5: Mucoepidermoid carcinoma | I5: T1 | K5: N2 | O5: III | Q5: לא רלוונטי | Y5: 3 | AA5: לא מתועד | AC5: לא מתועד | AE5: 3 — חמור | AG5: 3 | AI5: מעל 60 ק״מ | AK5: אמהרית | AM5: לא מתועד | AO5: לא מתועד | AQ5: רופא עור | AS5: כימותרפיה אינדוקציה | AU5: מחוץ לכללית | AW5: PET-CT | AY5: ועדה ← טיפול | BA5: מטופל | BC5: גידול שאינו ראש-צוואר
A6: PAL | B6: חך קשה | G6: Adenoid cystic carcinoma | I6: T2 | K6: N2a | O6: IV | Y6: 4 | AE6: לא ניתן לדירוג | AG6: 4–6 | AI6: לא מתועד | AK6: אחר | AQ6: מלר״ד | AS6: טיפול מערכתי | AU6: לא מתועד | AW6: הערכה דנטלית / עקירות | AY6: ניתוח ← טיפול משלים | BA6: לא ניתן לסיווג | BC6: טיפול פליאטיבי בלבד מלכתחילה
A7: LIP | B7: שפה | G7: Salivary duct carcinoma | I7: T3 | K7: N2b | O7: IVA | Y7: לא מתועד | AG7: 7 ומעלה | AK7: לא מתועד | AQ7: מחלקה אחרת בבית החולים | AS7: פליאטיבי | AW7: הערכה טרום-ניתוחית / הרדמה | BC7: רשומה חסרה מהותית
A8: RMT | B8: טריגון רטרומולרי | G8: Acinic cell carcinoma | I8: T4 | K8: N2c | O8: IVB | AG8: לא ניתן לדירוג | AQ8: פנייה עצמית | AS8: מעקב בלבד | AW8: הערכה קרדיולוגית | BC8: נפטר לפני תחילת טיפול
A9: TON | B9: שקד | G9: Carcinoma ex pleomorphic adenoma | I9: T4a | K9: N3 | O9: IVC | AQ9: אחר | AS9: לא טופל | AW9: PEG / תזונה | BC9: אחר
A10: BOT | B10: בסיס הלשון | G10: Papillary thyroid carcinoma | I10: T4b | K10: N3a | AQ10: לא מתועד | AW10: תור לחדר ניתוח
A11: OPX | B11: לוע הפה — אחר | G11: Follicular thyroid carcinoma | K11: N3b | AW11: תור לסימולציה / הקרנות
A12: NPC | B12: לוע האף | G12: Medullary thyroid carcinoma | AW12: הפניה למכון ההקרנות
A13: SGL | B13: גרון — סופרגלוטי | G13: Anaplastic thyroid carcinoma | AW13: תיאום בין מוסדות
A14: GLT | B14: גרון — גלוטי | G14: Mucosal melanoma | AW14: הצגה חוזרת בוועדה
A15: SBG | B15: גרון — סבגלוטי | G15: Sarcoma | AW15: אי-הגעה של המטופל
A16: HPX | B16: היפופרינקס | G16: Other | AW16: חוות דעת נוספת ביוזמת המטופל
A17: SNC | B17: אף וסינוסים | AW17: סירוב / התלבטות של המטופל
A18: PAR | B18: בלוטת הפרוטיד | AW18: מחלה נלווית / ייצוב רפואי
A19: SMG | B19: בלוטה תת-לסתית | AW19: סיבוך ניתוחי
A20: MSG | B20: בלוטות רוק זעירות | AW20: חופשה / סגירת שירות
A21: THY | B21: בלוטת התריס | AW21: אחר
A22: CUP | B22: גרורה צווארית ללא מוקד ראשוני | AW22: לא מתועד
A23: SKN | B23: עור ראש-צוואר
A24: OTH | B24: אחר
