Workbook

Sheet README
A1: MDT Loop · ENT — גיליון איסוף נתונים
A2: מחקר פיילוט, מרכז רפואי מאיר | B2: פרוטוקול גרסה 1.1 · עד 20 מטופלים · 3–6 חודשים · השוואה למאגר מטופלים קיים
A4: מספר מחקר (ת״ז מחקרית) | B4: מזהה רשמי אחד לכל מטופל, באנגלית: ENT-26-007-NPC-M-09
A5: ENT | B5: זרוע ההתערבות (HIS = מאגר המטופלים הקיים)
A6: 26 | B6: שנת דוח הפתולוגיה הממאירה
A7: 007 | B7: מספר רץ לפי סדר הכניסה — הוא שמבטיח שהמספר ייחודי
A8: NPC | B8: קוד אתר הגידול (רשימה מלאה בגיליון Lists)
A9: M | B9: צד: R ימין · L שמאל · M קו אמצע · B דו-צדדי
A10: 09 | B10: חודש דוח הפתולוגיה
A11: נוצר אוטומטית | B11: המספר נבנה מעצמו בעמודה A ברגע שמוזנים מספר רץ, אתר, צד ותאריך פתולוגיה. לאחר ההקצאה הוא קבוע: אם האתר מתוקן בהמשך, מתעדים זאת בהערות — ולא משנים את המספר (העתק ← הדבק כערך).
A13: כללים
A14: 1 | B14: אין בקובץ שם, תעודת זהות, תאריך לידה, כתובת או טלפון. הקישור בין מספר המחקר לזהות קיים רק בקובץ המפתח הנפרד, אצל החוקר הראשי (סעיף 8.6).
A15: 2 | B15: לפני כל פעולה קלינית — הפניה, זימון, החלטה — מאמתים את הזהות ברשומה של כללית בשני פרטים מזהים: שם מלא ומספר תעודת זהות.
A16: 3 | B16: מספר המחקר כולל אתר, צד וחודש, ולכן אינו מופיע מחוץ לסביבה המאובטחת. בפרסומים ובכנסים — מספר רץ ונתונים מקובצים בלבד.
A17: 4 | B17: עד לאישור אבטחת המידע של כללית וועדת הלסינקי — נתונים סינתטיים בלבד. אם האישור מתעכב, הקובץ נשמר על מחשב כללית בלבד.
A18: 5 | B18: תאריכים בפורמט dd/mm/yyyy. שדות הרשימה מקבלים ערכים מהרשימה בלבד.
A20: מקרא צבעים
A21: צהוב | B21: שדה להזנה
A22: אפור | B22: מחושב אוטומטית — לא לגעת
A23: כחול | B23: שורת דוגמה סינתטית (שורה 5) — אינה נספרת בסיכום
A24: אדום | B24: מרווח שלילי (תאריכים הפוכים) או מספר מחקר כפול
A26: הגיליונות
A27: Summary | B27: סיכום התוצאים — מתעדכן אוטומטית
A28: Patients | B28: 20 שורות — זרוע ההתערבות: זיהוי, דמוגרפיה, גידול, מועדים, מרווחים מחושבים
A29: Historical | B29: 60 שורות — מאגר המטופלים הקיים, 12 החודשים שקדמו להפעלה, אותם שדות
A30: MDT | B30: כל הצגה בוועדה בשורה: תוצאה, סיבת דחייה, שאלה קלינית, שלמות תיעוד לפי חוזר 18/2022
A31: Loops | B31: יומן הלולאות מהכלי: נפתחה, אושרה קבלה, נענתה, נסגרה — לפי דיסציפלינה
A32: Screening | B32: כל מטופל חדש שנדון בוועדה — לחישוב שיעור ההכללה ורצפת העצירה
A33: Staff | B33: פעילות הצוות בכלי לפי חודש ודיסציפלינה — אף פעם לא ברמת הפרט
A34: Dictionary | B34: הגדרת כל שדה והתוצא שהוא משרת
A35: Lists | B35: ערכי הרשימות הנפתחות

Sheet Summary
A1: סיכום התוצאים — מתעדכן אוטומטית
A2: חציון ו-IQR (לא ממוצע), לפי סעיף 7.1 בפרוטוקול. שורות הדוגמה אינן נספרות.
A4: אוכלוסייה | B4: התערבות | C4: בקרה היסטורית | D4: הערה
A5: מטופלים שנכללו | B5: =COUNTIF(Patients!$A$6:$A$25,"?*") -> 20 | C5: =COUNTIF(Historical!$A$6:$A$65,"?*") -> 0
A6: עם תוצא ראשוני (t0 ותחילת טיפול) | B6: =COUNT(Patients!$AY$6:$AY$25) -> 20 | C6: =COUNT(Historical!$AY$6:$AY$65) -> 0
A7: תוצא ראשוני — פתולוגיה ← טיפול (ימים) | B7: התערבות | C7: בקרה היסטורית | D7: הערה
A8: חציון | B8: =IF(COUNT(Patients!$AY$6:$AY$25)=0,"",MEDIAN(Patients!$AY$6:$AY$25)) -> 39.5 | C8: =IF(COUNT(Historical!$AY$6:$AY$65)=0,"",MEDIAN(Historical!$AY$6:$AY$65))
A9: רבעון ראשון (Q1) | B9: =IF(COUNT(Patients!$AY$6:$AY$25)=0,"",QUARTILE(Patients!$AY$6:$AY$25,1)) -> 28.5 | C9: =IF(COUNT(Historical!$AY$6:$AY$65)=0,"",QUARTILE(Historical!$AY$6:$AY$65,1))
A10: רבעון שלישי (Q3) | B10: =IF(COUNT(Patients!$AY$6:$AY$25)=0,"",QUARTILE(Patients!$AY$6:$AY$25,3)) -> 52.75 | C10: =IF(COUNT(Historical!$AY$6:$AY$65)=0,"",QUARTILE(Historical!$AY$6:$AY$65,3))
A11: מינימום | B11: =IF(COUNT(Patients!$AY$6:$AY$25)=0,"",MIN(Patients!$AY$6:$AY$25)) -> 18 | C11: =IF(COUNT(Historical!$AY$6:$AY$65)=0,"",MIN(Historical!$AY$6:$AY$65))
A12: מקסימום | B12: =IF(COUNT(Patients!$AY$6:$AY$25)=0,"",MAX(Patients!$AY$6:$AY$25)) -> 72 | C12: =IF(COUNT(Historical!$AY$6:$AY$65)=0,"",MAX(Historical!$AY$6:$AY$65))
A13: שיעור עד 30 יום | B13: =IFERROR(AVERAGE(Patients!$AZ$6:$AZ$25),"") -> 0.3 | C13: =IFERROR(AVERAGE(Historical!$AZ$6:$AZ$65),"") | D13: יעד: 30 יום מאבחנה לטיפול.
A14: שיעור מעל 60 יום | B14: =IFERROR(AVERAGE(Patients!$BA$6:$BA$25),"") -> 0.15 | C14: =IFERROR(AVERAGE(Historical!$BA$6:$BA$65),"") | D14: Liao 2019.
A15: שיעור מעל 67 יום | B15: =IFERROR(AVERAGE(Patients!$BB$6:$BB$25),"") -> 0.05 | C15: =IFERROR(AVERAGE(Historical!$BB$6:$BB$65),"") | D15: Murphy 2016.
A16: מקטעי המסלול — חציון (ימים) | B16: התערבות | C16: בקרה היסטורית | D16: הערה
A17: ייעוץ ← פתולוגיה | B17: =IFERROR(MEDIAN(Patients!$AV$6:$AV$25),"") | C17: =IFERROR(MEDIAN(Historical!$AV$6:$AV$65),"")
A18: פתולוגיה ← ועדה | B18: =IFERROR(MEDIAN(Patients!$AW$6:$AW$25),"") -> 13 | C18: =IFERROR(MEDIAN(Historical!$AW$6:$AW$65),"")
A19: החלטה ← טיפול | B19: =IFERROR(MEDIAN(Patients!$AX$6:$AX$25),"") -> 24.5 | C19: =IFERROR(MEDIAN(Historical!$AX$6:$AX$65),"")
A20: ניתוח ← החלטה שנייה | B20: =IFERROR(MEDIAN(Patients!$BF$6:$BF$25),"") -> 16 | C20: =IFERROR(MEDIAN(Historical!$BF$6:$BF$65),"")
A21: ניתוח ← טיפול משלים | B21: =IFERROR(MEDIAN(Patients!$BG$6:$BG$25),"") -> 43 | C21: =IFERROR(MEDIAN(Historical!$BG$6:$BG$65),"")
A22: ניתוח ≤30 יום מההחלטה (חוזר 1/2020) | B22: =IFERROR(AVERAGE(Patients!$BC$6:$BC$25),"") -> 1 | C22: =IFERROR(AVERAGE(Historical!$BC$6:$BC$65),"") | D22: מתוך המנותחים.
A23: טיפול משלים ≤42 יום מהניתוח | B23: =IFERROR(AVERAGE(Patients!$BH$6:$BH$25),"") -> 0.5 | C23: =IFERROR(AVERAGE(Historical!$BH$6:$BH$65),"") | D23: NCCN v1.2026, קטגוריה 2A.
A24: קיבולת — לבחינת השערת האפס (H0) | B24: התערבות | C24: בקרה היסטורית | D24: הערה
A25: הפניה ← ניתוח, חציון (ימים) | B25: =IFERROR(MEDIAN(Patients!$BD$6:$BD$25),"") -> 16.5 | C25: =IFERROR(MEDIAN(Historical!$BD$6:$BD$65),"")
A26: הפניה ← הקרנות, חציון (ימים) | B26: =IFERROR(MEDIAN(Patients!$BE$6:$BE$25),"") -> 37 | C26: =IFERROR(MEDIAN(Historical!$BE$6:$BE$65),"")
A27: הוועדה | B27: התערבות | D27: הערה
A28: הצגות בוועדה | B28: =COUNT(MDT!$D$5:$D$104) -> 26
A29: שיעור הצגות שנדחו בשל מידע חסר | B29: =IFERROR(COUNTIF(MDT!$E$5:$E$104,"נדחה — מידע חסר")/COUNT(MDT!$D$5:$D$104),"") -> 0.11538462 | D29: Ottevanger 2013: 5% ללא פתולוגיה/הדמיה.
A30: שיעור הצגות עם שאלה קלינית מפורשת | B30: =IFERROR(COUNTIF(MDT!$G$5:$G$104,"כן")/COUNTIF(MDT!$G$5:$G$104,"?*"),"") | D30: Ottevanger 2013: ~47%.
A31: שלמות תיעוד 18/2022, ממוצע | B31: =IFERROR(AVERAGE(MDT!$L$5:$L$104),"")
A32: הצגות למטופל, חציון | B32: =IFERROR(MEDIAN(Patients!$AR$6:$AR$25),"") -> 1 | C32: =IFERROR(MEDIAN(Historical!$AR$6:$AR$65),"")
A33: סיבות דחייה | B33: מספר
A34: פתולוגיה חסרה / חלקית | B34: =COUNTIF(MDT!$F$5:$F$104,"פתולוגיה חסרה / חלקית") -> 0
A35: צביעות / p16 / EBV ממתינות | B35: =COUNTIF(MDT!$F$5:$F$104,"צביעות / p16 / EBV ממתינות") -> 0
A36: הדמיה חסרה | B36: =COUNTIF(MDT!$F$5:$F$104,"הדמיה חסרה") -> 0
A37: PET-CT ממתין | B37: =COUNTIF(MDT!$F$5:$F$104,"PET-CT ממתין") -> 0
A38: הערכה דנטלית | B38: =COUNTIF(MDT!$F$5:$F$104,"הערכה דנטלית") -> 0
A39: הערכה קרדיולוגית / הרדמה | B39: =COUNTIF(MDT!$F$5:$F$104,"הערכה קרדיולוגית / הרדמה") -> 0
A40: המטופל לא הגיע / לא אותר | B40: =COUNTIF(MDT!$F$5:$F$104,"המטופל לא הגיע / לא אותר") -> 0
A41: חוות דעת נוספת | B41: =COUNTIF(MDT!$F$5:$F$104,"חוות דעת נוספת") -> 0
...

Sheet Patients
A1: זרוע ההתערבות — עד 20 מטופלים (MDT Loop · ENT) | H1: צהוב = להזנה · אפור = מחושב אוטומטית · כחול = שורת דוגמה סינתטית (אינה נספרת)
A2: זיהוי | E2: כניסה | G2: דמוגרפיה | O2: גידול | X2: מועדים | AG2: קיבולת | AI2: מועדים | AM2: הצגה חוזרת | AP2: גורמי עיכוב | AR2: תהליך | AV2: מרווחים (ימים) | BI2: הערות
A3: מספר מחקר (ת״ז מחקרית) | B3: מספר רץ | C3: קוד אתר | D3: צד | E3: תאריך הסכמה מדעת | F3: סטטוס במחקר | G3: גיל באבחנה | H3: מין | I3: ECOG | J3: עישון | K3: שנות קופסה | L3: אלכוהול | M3: מחלות רקע (ACE-27) | N3: מרחק מגורים | O3: היסטולוגיה | P3: cT | Q3: cN | R3: cM | S3: שלב קליני | T3: p16 / HPV | U3: EBV | V3: pT | W3: pN | X3: ייעוץ ראשון אא״ג | Y3: ביופסיה | Z3: דוח פתולוגיה ממאירה (t = 0) | AA3: הדמיית שלב CT / MRI | AB3: PET-CT | AC3: הצגה ראשונה בוועדה | AD3: החלטת ועדה | AE3: מודאליות מתוכננת | AF3: אתר טיפול | AG3: הפניה לחדר ניתוח | AH3: הפניה למכון ההקרנות | AI3: תחילת טיפול מכריע ראשון | AJ3: מודאליות בפועל | AK3: תואם החלטת ועדה | AL3: סיבת אי-התאמה | AM3: הצגה חוזרת בוועדה | AN3: החלטה שנייה | AO3: תחילת טיפול משלים | AP3: נדרשה הערכה דנטלית | AQ3: PEG מניעתי | AR3: מספר הצגות בוועדה | AS3: דחיות בשל מידע חסר | AT3: סגירת מעקב | AU3: סגר את המעקב | AV3: ייעוץ ← פתולוגיה | AW3: פתולוגיה ← ועדה | AX3: החלטה ← טיפול | AY3: פתולוגיה ← טיפול · תוצא ראשוני | AZ3: עד 30 יום | BA3: מעל 60 יום | BB3: מעל 67 יום | BC3: ניתוח ≤30 יום מההחלטה (חוזר 1/2020) | BD3: הפניה ← ניתוח | BE3: הפניה ← הקרנות | BF3: ניתוח ← החלטה שנייה | BG3: ניתוח ← טיפול משלים | BH3: משלים ≤42 יום | BI3: הערות (ללא פרטים מזהים)
A4: id | B4: seq | C4: site | D4: side | E4: consent | F4: status | G4: age | H4: sex | I4: ecog | J4: smoke | K4: py | L4: alc | M4: ace | N4: dist | O4: hist | P4: cT | Q4: cN | R4: cM | S4: stage | T4: p16 | U4: ebv | V4: pT | W4: pN | X4: consult | Y4: biopsy | Z4: t0 | AA4: ct | AB4: pet | AC4: mdt1 | AD4: dec | AE4: pmod | AF4: txsite | AG4: orref | AH4: rtref | AI4: tx | AJ4: amod | AK4: conc | AL4: ncr | AM4: mdt2 | AN4: dec2 | AO4: adj | AP4: dental | AQ4: peg | AR4: nres | AS4: ndef | AT4: close | AU4: closer | AV4: i_cp | AW4: i_pm | AX4: i_dt | AY4: i_pt | AZ4: f30 | BA4: f60 | BB4: f67 | BC4: moh | BD4: i_or | BE4: i_rt | BF4: i_s2 | BG4: i_adj | BH4: f42 | BI4: note
A5: =IF(OR(B5="",C5="",D5="",Z5=""),"","ENT-"&RIGHT(YEAR(Z5),2)&"-"&TEXT(B5,"000")&"-"&C5&"-"&D5&"-"&TEXT(MONTH(Z5),"00")) -> ENT-26-000-NPC-M-09 | B5: 0 | C5: NPC | D5: M | E5: 46282 | F5: פעיל | G5: 54 | H5: ז | I5: 1 | J5: עישן בעבר | K5: 20 | L5: מתון | M5: 1 — קל | N5: 10–30 ק״מ | O5: Nasopharyngeal carcinoma (WHO) | P5: T2 | Q5: N2 | R5: M0 | S5: III | T5: לא רלוונטי | U5: חיובי | X5: 46264 | Y5: 46268 | Z5: 46275 | AA5: 46279 | AB5: 46286 | AC5: 46289 | AD5: 46289 | AE5: כימו-הקרנות | AF5: דוידוף | AH5: 46290 | AI5: 46315 | AJ5: כימו-הקרנות | AK5: כן | AP5: כן | AQ5: לא | AR5: =IF(A5="","",COUNTIF(MDT!$B$5:$B$104,A5)) -> 0 | AS5: =IF(A5="","",COUNTIFS(MDT!$B$5:$B$104,A5,MDT!$E$5:$E$104,"נדחה — מידע חסר")) -> 0 | AT5: 46315 | AU5: מנהל תחום אא״ג | AV5: =IF(OR(X5="",Z5=""),"",Z5-X5) -> 11 | AW5: =IF(OR(Z5="",AC5=""),"",AC5-Z5) -> 14 | AX5: =IF(OR(AD5="",AI5=""),"",AI5-AD5) -> 26 | AY5: =IF(OR(Z5="",AI5=""),"",AI5-Z5) -> 40 | AZ5: =IF(AY5="","",IF(AY5<=30,1,0)) -> 0 | BA5: =IF(AY5="","",IF(AY5>60,1,0)) -> 0 | BB5: =IF(AY5="","",IF(AY5>67,1,0)) -> 0 | BC5: =IF(OR(AJ5<>"ניתוח",AX5=""),"",IF(AX5<=30,1,0)) | BD5: =IF(OR(AG5="",AI5="",AJ5<>"ניתוח"),"",AI5-AG5) | BE5: =IF(OR(AH5="",AI5="",AND(AJ5<>"הקרנות",AJ5<>"כימו-הקרנות")),"",AI5-AH5) -> 25 | BF5: =IF(OR(AJ5<>"ניתוח",AI5="",AN5=""),"",AN5-AI5) | BG5: =IF(OR(AJ5<>"ניתוח",AI5="",AO5=""),"",AO5-AI5) | BH5: =IF(BG5="","",IF(BG5<=42,1,0)) | BI5: שורת דוגמה סינתטית — ENT-26-000-NPC-M-09
A6: =IF(OR(B6="",C6="",D6="",Z6=""),"","ENT-"&RIGHT(YEAR(Z6),2)&"-"&TEXT(B6,"000")&"-"&C6&"-"&D6&"-"&TEXT(MONTH(Z6),"00")) -> ENT-26-001-OT-L-06 | B6: 1 | C6: OT | D6: L | G6: 61 | H6: ז | I6: 0 | P6: T2 | Q6: N1 | R6: M0 | S6: III | T6: לא רלוונטי | Z6: 46174 | AC6: 46184 | AD6: 46184 | AE6: ניתוח | AG6: 46185 | AI6: 46200 | AJ6: ניתוח | AN6: 46212 | AO6: 46240 | AP6: כן | AQ6: לא | AR6: =IF(A6="","",COUNTIF(MDT!$B$5:$B$104,A6)) -> 2 | AS6: =IF(A6="","",COUNTIFS(MDT!$B$5:$B$104,A6,MDT!$E$5:$E$104,"נדחה — מידע חסר")) -> 0 | AV6: =IF(OR(X6="",Z6=""),"",Z6-X6) | AW6: =IF(OR(Z6="",AC6=""),"",AC6-Z6) -> 10 | AX6: =IF(OR(AD6="",AI6=""),"",AI6-AD6) -> 16 | AY6: =IF(OR(Z6="",AI6=""),"",AI6-Z6) -> 26 | AZ6: =IF(AY6="","",IF(AY6<=30,1,0)) -> 1 | BA6: =IF(AY6="","",IF(AY6>60,1,0)) -> 0 | BB6: =IF(AY6="","",IF(AY6>67,1,0)) -> 0 | BC6: =IF(OR(AJ6<>"ניתוח",AX6=""),"",IF(AX6<=30,1,0)) -> 1 | BD6: =IF(OR(AG6="",AI6="",AJ6<>"ניתוח"),"",AI6-AG6) -> 15 | BE6: =IF(OR(AH6="",AI6="",AND(AJ6<>"הקרנות",AJ6<>"כימו-הקרנות")),"",AI6-AH6) | BF6: =IF(OR(AJ6<>"ניתוח",AI6="",AN6=""),"",AN6-AI6) -> 12 | BG6: =IF(OR(AJ6<>"ניתוח",AI6="",AO6=""),"",AO6-AI6) -> 40 | BH6: =IF(BG6="","",IF(BG6<=42,1,0)) -> 1
A7: =IF(OR(B7="",C7="",D7="",Z7=""),"","ENT-"&RIGHT(YEAR(Z7),2)&"-"&TEXT(B7,"000")&"-"&C7&"-"&D7&"-"&TEXT(MONTH(Z7),"00")) -> ENT-26-002-NPC-M-06 | B7: 2 | C7: NPC | D7: M | G7: 48 | H7: ז | I7: 0 | P7: T2 | Q7: N2 | R7: M0 | S7: III | T7: לא רלוונטי | Z7: 46175 | AC7: 46191 | AD7: 46191 | AE7: כימו-הקרנות | AH7: 46192 | AI7: 46224 | AJ7: כימו-הקרנות | AP7: כן | AQ7: כן | AR7: =IF(A7="","",COUNTIF(MDT!$B$5:$B$104,A7)) -> 1 | AS7: =IF(A7="","",COUNTIFS(MDT!$B$5:$B$104,A7,MDT!$E$5:$E$104,"נדחה — מידע חסר")) -> 0 | AV7: =IF(OR(X7="",Z7=""),"",Z7-X7) | AW7: =IF(OR(Z7="",AC7=""),"",AC7-Z7) -> 16 | AX7: =IF(OR(AD7="",AI7=""),"",AI7-AD7) -> 33 | AY7: =IF(OR(Z7="",AI7=""),"",AI7-Z7) -> 49 | AZ7: =IF(AY7="","",IF(AY7<=30,1,0)) -> 0 | BA7: =IF(AY7="","",IF(AY7>60,1,0)) -> 0 | BB7: =IF(AY7="","",IF(AY7>67,1,0)) -> 0 | BC7: =IF(OR(AJ7<>"ניתוח",AX7=""),"",IF(AX7<=30,1,0)) | BD7: =IF(OR(AG7="",AI7="",AJ7<>"ניתוח"),"",AI7-AG7) | BE7: =IF(OR(AH7="",AI7="",AND(AJ7<>"הקרנות",AJ7<>"כימו-הקרנות")),"",AI7-AH7) -> 32 | BF7: =IF(OR(AJ7<>"ניתוח",AI7="",AN7=""),"",AN7-AI7) | BG7: =IF(OR(AJ7<>"ניתוח",AI7="",AO7=""),"",AO7-AI7) | BH7: =IF(BG7="","",IF(BG7<=42,1,0))
A8: =IF(OR(B8="",C8="",D8="",Z8=""),"","ENT-"&RIGHT(YEAR(Z8),2)&"-"&TEXT(B8,"000")&"-"&C8&"-"&D8&"-"&TEXT(MONTH(Z8),"00")) -> ENT-26-003-FOM-M-06 | B8: 3 | C8: FOM | D8: M | G8: 57 | H8: נ | I8: 0 | P8: T2 | Q8: N0 | R8: M0 | S8: II | T8: לא רלוונטי | Z8: 46176 | AC8: 46184 | AD8: 46184 | AE8: ניתוח | AG8: 46185 | AI8: 46198 | AJ8: ניתוח | AP8: לא | AQ8: לא | AR8: =IF(A8="","",COUNTIF(MDT!$B$5:$B$104,A8)) -> 1 | AS8: =IF(A8="","",COUNTIFS(MDT!$B$5:$B$104,A8,MDT!$E$5:$E$104,"נדחה — מידע חסר")) -> 0 | AV8: =IF(OR(X8="",Z8=""),"",Z8-X8) | AW8: =IF(OR(Z8="",AC8=""),"",AC8-Z8) -> 8 | AX8: =IF(OR(AD8="",AI8=""),"",AI8-AD8) -> 14 | AY8: =IF(OR(Z8="",AI8=""),"",AI8-Z8) -> 22 | AZ8: =IF(AY8="","",IF(AY8<=30,1,0)) -> 1 | BA8: =IF(AY8="","",IF(AY8>60,1,0)) -> 0 | BB8: =IF(AY8="","",IF(AY8>67,1,0)) -> 0 | BC8: =IF(OR(AJ8<>"ניתוח",AX8=""),"",IF(AX8<=30,1,0)) -> 1 | BD8: =IF(OR(AG8="",AI8="",AJ8<>"ניתוח"),"",AI8-AG8) -> 13 | BE8: =IF(OR(AH8="",AI8="",AND(AJ8<>"הקרנות",AJ8<>"כימו-הקרנות")),"",AI8-AH8) | BF8: =IF(OR(AJ8<>"ניתוח",AI8="",AN8=""),"",AN8-AI8) | BG8: =IF(OR(AJ8<>"ניתוח",AI8="",AO8=""),"",AO8-AI8) | BH8: =IF(BG8="","",IF(BG8<=42,1,0))
A9: =IF(OR(B9="",C9="",D9="",Z9=""),"","ENT-"&RIGHT(YEAR(Z9),2)&"-"&TEXT(B9,"000")&"-"&C9&"-"&D9&"-"&TEXT(MONTH(Z9),"00")) -> ENT-26-004-BOT-L-06 | B9: 4 | C9: BOT | D9: L | G9: 62 | H9: נ | I9: 1 | P9: T3 | Q9: N2 | R9: M0 | S9: III | T9: חיובי | Z9: 46177 | AC9: 46191 | AD9: 46191 | AE9: כימו-הקרנות | AH9: 46192 | AI9: 46232 | AJ9: כימו-הקרנות | AP9: כן | AQ9: כן | AR9: =IF(A9="","",COUNTIF(MDT!$B$5:$B$104,A9)) -> 1 | AS9: =IF(A9="","",COUNTIFS(MDT!$B$5:$B$104,A9,MDT!$E$5:$E$104,"נדחה — מידע חסר")) -> 0 | AV9: =IF(OR(X9="",Z9=""),"",Z9-X9) | AW9: =IF(OR(Z9="",AC9=""),"",AC9-Z9) -> 14 | AX9: =IF(OR(AD9="",AI9=""),"",AI9-AD9) -> 41 | AY9: =IF(OR(Z9="",AI9=""),"",AI9-Z9) -> 55 | AZ9: =IF(AY9="","",IF(AY9<=30,1,0)) -> 0 | BA9: =IF(AY9="","",IF(AY9>60,1,0)) -> 0 | BB9: =IF(AY9="","",IF(AY9>67,1,0)) -> 0 | BC9: =IF(OR(AJ9<>"ניתוח",AX9=""),"",IF(AX9<=30,1,0)) | BD9: =IF(OR(AG9="",AI9="",AJ9<>"ניתוח"),"",AI9-AG9) | BE9: =IF(OR(AH9="",AI9="",AND(AJ9<>"הקרנות",AJ9<>"כימו-הקרנות")),"",AI9-AH9) -> 40 | BF9: =IF(OR(AJ9<>"ניתוח",AI9="",AN9=""),"",AN9-AI9) | BG9: =IF(OR(AJ9<>"ניתוח",AI9="",AO9=""),"",AO9-AI9) | BH9: =IF(BG9="","",IF(BG9<=42,1,0))
A10: =IF(OR(B10="",C10="",D10="",Z10=""),"","ENT-"&RIGHT(YEAR(Z10),2)&"-"&TEXT(B10,"000")&"-"&C10&"-"&D10&"-"&TEXT(MONTH(Z10),"00")) -> ENT-26-005-GLT-R-06 | B10: 5 | C10: GLT | D10: R | G10: 68 | H10: ז | I10: 1 | P10: T1a | Q10: N0 | R10: M0 | S10: I | T10: לא רלוונטי | Z10: 46178 | AC10: 46184 | AD10: 46184 | AE10: ניתוח | AG10: 46185 | AI10: 46196 | AJ10: ניתוח | AP10: לא | AQ10: לא | AR10: =IF(A10="","",COUNTIF(MDT!$B$5:$B$104,A10)) -> 1 | AS10: =IF(A10="","",COUNTIFS(MDT!$B$5:$B$104,A10,MDT!$E$5:$E$104,"נדחה — מידע חסר")) -> 0 | AV10: =IF(OR(X10="",Z10=""),"",Z10-X10) | AW10: =IF(OR(Z10="",AC10=""),"",AC10-Z10) -> 6 | AX10: =IF(OR(AD10="",AI10=""),"",AI10-AD10) -> 12 | AY10: =IF(OR(Z10="",AI10=""),"",AI10-Z10) -> 18 | AZ10: =IF(AY10="","",IF(AY10<=30,1,0)) -> 1 | BA10: =IF(AY10="","",IF(AY10>60,1,0)) -> 0 | BB10: =IF(AY10="","",IF(AY10>67,1,0)) -> 0 | BC10: =IF(OR(AJ10<>"ניתוח",AX10=""),"",IF(AX10<=30,1,0)) -> 1 | BD10: =IF(OR(AG10="",AI10="",AJ10<>"ניתוח"),"",AI10-AG10) -> 11 | BE10: =IF(OR(AH10="",AI10="",AND(AJ10<>"הקרנות",AJ10<>"כימו-הקרנות")),"",AI10-AH10) | BF10: =IF(OR(AJ10<>"ניתוח",AI10="",AN10=""),"",AN10-AI10) | BG10: =IF(OR(AJ10<>"ניתוח",AI10="",AO10=""),"",AO10-AI10) | BH10: =IF(BG10="","",IF(BG10<=42,1,0))
A11: =IF(OR(B11="",C11="",D11="",Z11=""),"","ENT-"&RIGHT(YEAR(Z11),2)&"-"&TEXT(B11,"000")&"-"&C11&"-"&D11&"-"&TEXT(MONTH(Z11),"00")) -> ENT-26-006-GLT-L-06 | B11: 6 | C11: GLT | D11: L | G11: 71 | H11: ז | I11: 1 | P11: T2 | Q11: N0 | R11: M0 | S11: II | T11: לא רלוונטי | Z11: 46178 | AC11: 46191 | AD11: 46191 | AE11: הקרנות | AH11: 46192 | AI11: 46213 | AJ11: הקרנות | AP11: לא | AQ11: לא | AR11: =IF(A11="","",COUNTIF(MDT!$B$5:$B$104,A11)) -> 1 | AS11: =IF(A11="","",COUNTIFS(MDT!$B$5:$B$104,A11,MDT!$E$5:$E$104,"נדחה — מידע חסר")) -> 0 | AV11: =IF(OR(X11="",Z11=""),"",Z11-X11) | AW11: =IF(OR(Z11="",AC11=""),"",AC11-Z11) -> 13 | AX11: =IF(OR(AD11="",AI11=""),"",AI11-AD11) -> 22 | AY11: =IF(OR(Z11="",AI11=""),"",AI11-Z11) -> 35 | AZ11: =IF(AY11="","",IF(AY11<=30,1,0)) -> 0 | BA11: =IF(AY11="","",IF(AY11>60,1,0)) -> 0 | BB11: =IF(AY11="","",IF(AY11>67,1,0)) -> 0 | BC11: =IF(OR(AJ11<>"ניתוח",AX11=""),"",IF(AX11<=30,1,0)) | BD11: =IF(OR(AG11="",AI11="",AJ11<>"ניתוח"),"",AI11-AG11) | BE11: =IF(OR(AH11="",AI11="",AND(AJ11<>"הקרנות",AJ11<>"כימו-הקרנות")),"",AI11-AH11) -> 21 | BF11: =IF(OR(AJ11<>"ניתוח",AI11="",AN11=""),"",AN11-AI11) | BG11: =IF(OR(AJ11<>"ניתוח",AI11="",AO11=""),"",AO11-AI11) | BH11: =IF(BG11="","",IF(BG11<=42,1,0))
A12: =IF(OR(B12="",C12="",D12="",Z12=""),"","ENT-"&RIGHT(YEAR(Z12),2)&"-"&TEXT(B12,"000")&"-"&C12&"-"&D12&"-"&TEXT(MONTH(Z12),"00")) -> ENT-26-007-HPX-R-06 | B12: 7 | C12: HPX | D12: R | G12: 66 | H12: ז | I12: 1 | P12: T3 | Q12: N2b | R12: M0 | S12: IVA | T12: לא רלוונטי | Z12: 46179 | AC12: 46198 | AD12: 46205 | AE12: כימו-הקרנות | AH12: 46206 | AI12: 46245 | AJ12: כימו-הקרנות | AP12: כן | AQ12: כן | AR12: =IF(A12="","",COUNTIF(MDT!$B$5:$B$104,A12)) -> 2 | AS12: =IF(A12="","",COUNTIFS(MDT!$B$5:$B$104,A12,MDT!$E$5:$E$104,"נדחה — מידע חסר")) -> 1 | AV12: =IF(OR(X12="",Z12=""),"",Z12-X12) | AW12: =IF(OR(Z12="",AC12=""),"",AC12-Z12) -> 19 | AX12: =IF(OR(AD12="",AI12=""),"",AI12-AD12) -> 40 | AY12: =IF(OR(Z12="",AI12=""),"",AI12-Z12) -> 66 | AZ12: =IF(AY12="","",IF(AY12<=30,1,0)) -> 0 | BA12: =IF(AY12="","",IF(AY12>60,1,0)) -> 1 | BB12: =IF(AY12="","",IF(AY12>67,1,0)) -> 0 | BC12: =IF(OR(AJ12<>"ניתוח",AX12=""),"",IF(AX12<=30,1,0)) | BD12: =IF(OR(AG12="",AI12="",AJ12<>"ניתוח"),"",AI12-AG12) | BE12: =IF(OR(AH12="",AI12="",AND(AJ12<>"הקרנות",AJ12<>"כימו-הקרנות")),"",AI12-AH12) -> 39 | BF12: =IF(OR(AJ12<>"ניתוח",AI12="",AN12=""),"",AN12-AI12) | BG12: =IF(OR(AJ12<>"ניתוח",AI12="",AO12=""),"",AO12-AI12) | BH12: =IF(BG12="","",IF(BG12<=42,1,0))
A13: =IF(OR(B13="",C13="",D13="",Z13=""),"","ENT-"&RIGHT(YEAR(Z13),2)&"-"&TEXT(B13,"000")&"-"&C13&"-"&D13&"-"&TEXT(MONTH(Z13),"00")) -> ENT-26-008-THY-B-06 | B13: 8 | C13: THY | D13: B | G13: 49 | H13: נ | I13: 0 | P13: T2 | Q13: N1a | R13: M0 | S13: I | T13: לא רלוונטי | Z13: 46181 | AC13: 46191 | AD13: 46191 | AE13: ניתוח | AG13: 46192 | AI13: 46210 | AJ13: ניתוח | AP13: לא | AQ13: לא | AR13: =IF(A13="","",COUNTIF(MDT!$B$5:$B$104,A13)) -> 1 | AS13: =IF(A13="","",COUNTIFS(MDT!$B$5:$B$104,A13,MDT!$E$5:$E$104,"נדחה — מידע חסר")) -> 0 | AV13: =IF(OR(X13="",Z13=""),"",Z13-X13) | AW13: =IF(OR(Z13="",AC13=""),"",AC13-Z13) -> 10 | AX13: =IF(OR(AD13="",AI13=""),"",AI13-AD13) -> 19 | AY13: =IF(OR(Z13="",AI13=""),"",AI13-Z13) -> 29 | AZ13: =IF(AY13="","",IF(AY13<=30,1,0)) -> 1 | BA13: =IF(AY13="","",IF(AY13>60,1,0)) -> 0 | BB13: =IF(AY13="","",IF(AY13>67,1,0)) -> 0 | BC13: =IF(OR(AJ13<>"ניתוח",AX13=""),"",IF(AX13<=30,1,0)) -> 1 | BD13: =IF(OR(AG13="",AI13="",AJ13<>"ניתוח"),"",AI13-AG13) -> 18 | BE13: =IF(OR(AH13="",AI13="",AND(AJ13<>"הקרנות",AJ13<>"כימו-הקרנות")),"",AI13-AH13) | BF13: =IF(OR(AJ13<>"ניתוח",AI13="",AN13=""),"",AN13-AI13) | BG13: =IF(OR(AJ13<>"ניתוח",AI13="",AO13=""),"",AO13-AI13) | BH13: =IF(BG13="","",IF(BG13<=42,1,0))
A14: =IF(OR(B14="",C14="",D14="",Z14=""),"","ENT-"&RIGHT(YEAR(Z14),2)&"-"&TEXT(B14,"000")&"-"&C14&"-"&D14&"-"&TEXT(MONTH(Z14),"00")) -> ENT-26-009-HPX-L-06 | B14: 9 | C14: HPX | D14: L | G14: 77 | H14: ז | I14: 2 | P14: T2 | Q14: N2c | R14: M0 | S14: IVA | T14: לא רלוונטי | Z14: 46181 | AC14: 46198 | AD14: 46205 | AE14: הקרנות | AH14: 46206 | AI14: 46253 | AJ14: הקרנות | AP14: כן | AQ14: כן | AR14: =IF(A14="","",COUNTIF(MDT!$B$5:$B$104,A14)) -> 2 | AS14: =IF(A14="","",COUNTIFS(MDT!$B$5:$B$104,A14,MDT!$E$5:$E$104,"נדחה — מידע חסר")) -> 1 | AV14: =IF(OR(X14="",Z14=""),"",Z14-X14) | AW14: =IF(OR(Z14="",AC14=""),"",AC14-Z14) -> 17 | AX14: =IF(OR(AD14="",AI14=""),"",AI14-AD14) -> 48 | AY14: =IF(OR(Z14="",AI14=""),"",AI14-Z14) -> 72 | AZ14: =IF(AY14="","",IF(AY14<=30,1,0)) -> 0 | BA14: =IF(AY14="","",IF(AY14>60,1,0)) -> 1 | BB14: =IF(AY14="","",IF(AY14>67,1,0)) -> 1 | BC14: =IF(OR(AJ14<>"ניתוח",AX14=""),"",IF(AX14<=30,1,0)) | BD14: =IF(OR(AG14="",AI14="",AJ14<>"ניתוח"),"",AI14-AG14) | BE14: =IF(OR(AH14="",AI14="",AND(AJ14<>"הקרנות",AJ14<>"כימו-הקרנות")),"",AI14-AH14) -> 47 | BF14: =IF(OR(AJ14<>"ניתוח",AI14="",AN14=""),"",AN14-AI14) | BG14: =IF(OR(AJ14<>"ניתוח",AI14="",AO14=""),"",AO14-AI14) | BH14: =IF(BG14="","",IF(BG14<=42,1,0))
A15: =IF(OR(B15="",C15="",D15="",Z15=""),"","ENT-"&RIGHT(YEAR(Z15),2)&"-"&TEXT(B15,"000")&"-"&C15&"-"&D15&"-"&TEXT(MONTH(Z15),"00")) -> ENT-26-010-TON-L-06 | B15: 10 | C15: TON | D15: L | G15: 53 | H15: נ | I15: 0 | P15: T2 | Q15: N1 | R15: M0 | S15: I | T15: חיובי | Z15: 46182 | AC15: 46191 | AD15: 46191 | AE15: כימו-הקרנות | AH15: 46192 | AI15: 46228 | AJ15: כימו-הקרנות | AP15: כן | AQ15: לא | AR15: =IF(A15="","",COUNTIF(MDT!$B$5:$B$104,A15)) -> 1 | AS15: =IF(A15="","",COUNTIFS(MDT!$B$5:$B$104,A15,MDT!$E$5:$E$104,"נדחה — מידע חסר")) -> 0 | AV15: =IF(OR(X15="",Z15=""),"",Z15-X15) | AW15: =IF(OR(Z15="",AC15=""),"",AC15-Z15) -> 9 | AX15: =IF(OR(AD15="",AI15=""),"",AI15-AD15) -> 37 | AY15: =IF(OR(Z15="",AI15=""),"",AI15-Z15) -> 46 | AZ15: =IF(AY15="","",IF(AY15<=30,1,0)) -> 0 | BA15: =IF(AY15="","",IF(AY15>60,1,0)) -> 0 | BB15: =IF(AY15="","",IF(AY15>67,1,0)) -> 0 | BC15: =IF(OR(AJ15<>"ניתוח",AX15=""),"",IF(AX15<=30,1,0)) | BD15: =IF(OR(AG15="",AI15="",AJ15<>"ניתוח"),"",AI15-AG15) | BE15: =IF(OR(AH15="",AI15="",AND(AJ15<>"הקרנות",AJ15<>"כימו-הקרנות")),"",AI15-AH15) -> 36 | BF15: =IF(OR(AJ15<>"ניתוח",AI15="",AN15=""),"",AN15-AI15) | BG15: =IF(OR(AJ15<>"ניתוח",AI15="",AO15=""),"",AO15-AI15) | BH15: =IF(BG15="","",IF(BG15<=42,1,0))
A16: =IF(OR(B16="",C16="",D16="",Z16=""),"","ENT-"&RIGHT(YEAR(Z16),2)&"-"&TEXT(B16,"000")&"-"&C16&"-"&D16&"-"&TEXT(MONTH(Z16),"00")) -> ENT-26-011-PAR-R-06 | B16: 11 | C16: PAR | D16: R | G16: 72 | H16: ז | I16: 1 | P16: T3 | Q16: N0 | R16: M0 | S16: III | T16: לא רלוונטי | Z16: 46183 | AC16: 46198 | AD16: 46198 | AE16: ניתוח | AG16: 46199 | AI16: 46217 | AJ16: ניתוח | AN16: 46233 | AO16: 46263 | AP16: לא | AQ16: לא | AR16: =IF(A16="","",COUNTIF(MDT!$B$5:$B$104,A16)) -> 2 | AS16: =IF(A16="","",COUNTIFS(MDT!$B$5:$B$104,A16,MDT!$E$5:$E$104,"נדחה — מידע חסר")) -> 0 | AV16: =IF(OR(X16="",Z16=""),"",Z16-X16) | AW16: =IF(OR(Z16="",AC16=""),"",AC16-Z16) -> 15 | AX16: =IF(OR(AD16="",AI16=""),"",AI16-AD16) -> 19 | AY16: =IF(OR(Z16="",AI16=""),"",AI16-Z16) -> 34 | AZ16: =IF(AY16="","",IF(AY16<=30,1,0)) -> 0 | BA16: =IF(AY16="","",IF(AY16>60,1,0)) -> 0 | BB16: =IF(AY16="","",IF(AY16>67,1,0)) -> 0 | BC16: =IF(OR(AJ16<>"ניתוח",AX16=""),"",IF(AX16<=30,1,0)) -> 1 | BD16: =IF(OR(AG16="",AI16="",AJ16<>"ניתוח"),"",AI16-AG16) -> 18 | BE16: =IF(OR(AH16="",AI16="",AND(AJ16<>"הקרנות",AJ16<>"כימו-הקרנות")),"",AI16-AH16) | BF16: =IF(OR(AJ16<>"ניתוח",AI16="",AN16=""),"",AN16-AI16) -> 16 | BG16: =IF(OR(AJ16<>"ניתוח",AI16="",AO16=""),"",AO16-AI16) -> 46 | BH16: =IF(BG16="","",IF(BG16<=42,1,0)) -> 0
A17: =IF(OR(B17="",C17="",D17="",Z17=""),"","ENT-"&RIGHT(YEAR(Z17),2)&"-"&TEXT(B17,"000")&"-"&C17&"-"&D17&"-"&TEXT(MONTH(Z17),"00")) -> ENT-26-012-CUP-R-06 | B17: 12 | C17: CUP | D17: R | G17: 69 | H17: ז | I17: 1 | P17: T0 | Q17: N1 | R17: M0 | S17: I | T17: חיובי | Z17: 46184 | AC17: 46205 | AD17: 46205 | AE17: כימו-הקרנות | AH17: 46206 | AI17: 46242 | AJ17: כימו-הקרנות | AP17: כן | AQ17: כן | AR17: =IF(A17="","",COUNTIF(MDT!$B$5:$B$104,A17)) -> 1 | AS17: =IF(A17="","",COUNTIFS(MDT!$B$5:$B$104,A17,MDT!$E$5:$E$104,"נדחה — מידע חסר")) -> 0 | AV17: =IF(OR(X17="",Z17=""),"",Z17-X17) | AW17: =IF(OR(Z17="",AC17=""),"",AC17-Z17) -> 21 | AX17: =IF(OR(AD17="",AI17=""),"",AI17-AD17) -> 37 | AY17: =IF(OR(Z17="",AI17=""),"",AI17-Z17) -> 58 | AZ17: =IF(AY17="","",IF(AY17<=30,1,0)) -> 0 | BA17: =IF(AY17="","",IF(AY17>60,1,0)) -> 0 | BB17: =IF(AY17="","",IF(AY17>67,1,0)) -> 0 | BC17: =IF(OR(AJ17<>"ניתוח",AX17=""),"",IF(AX17<=30,1,0)) | BD17: =IF(OR(AG17="",AI17="",AJ17<>"ניתוח"),"",AI17-AG17) | BE17: =IF(OR(AH17="",AI17="",AND(AJ17<>"הקרנות",AJ17<>"כימו-הקרנות")),"",AI17-AH17) -> 36 | BF17: =IF(OR(AJ17<>"ניתוח",AI17="",AN17=""),"",AN17-AI17) | BG17: =IF(OR(AJ17<>"ניתוח",AI17="",AO17=""),"",AO17-AI17) | BH17: =IF(BG17="","",IF(BG17<=42,1,0))
A18: =IF(OR(B18="",C18="",D18="",Z18=""),"","ENT-"&RIGHT(YEAR(Z18),2)&"-"&TEXT(B18,"000")&"-"&C18&"-"&D18&"-"&TEXT(MONTH(Z18),"00")) -> ENT-26-013-BUC-L-06 | B18: 13 | C18: BUC | D18: L | G18: 64 | H18: נ | I18: 1 | P18: T3 | Q18: N2b | R18: M0 | S18: IVA | T18: לא רלוונטי | Z18: 46185 | AC18: 46198 | AD18: 46205 | AE18: ניתוח | AG18: 46206 | AI18: 46223 | AJ18: ניתוח | AN18: 46240 | AP18: כן | AQ18: לא | AR18: =IF(A18="","",COUNTIF(MDT!$B$5:$B$104,A18)) -> 3 | AS18: =IF(A18="","",COUNTIFS(MDT!$B$5:$B$104,A18,MDT!$E$5:$E$104,"נדחה — מידע חסר")) -> 1 | AV18: =IF(OR(X18="",Z18=""),"",Z18-X18) | AW18: =IF(OR(Z18="",AC18=""),"",AC18-Z18) -> 13 | AX18: =IF(OR(AD18="",AI18=""),"",AI18-AD18) -> 18 | AY18: =IF(OR(Z18="",AI18=""),"",AI18-Z18) -> 38 | AZ18: =IF(AY18="","",IF(AY18<=30,1,0)) -> 0 | BA18: =IF(AY18="","",IF(AY18>60,1,0)) -> 0 | BB18: =IF(AY18="","",IF(AY18>67,1,0)) -> 0 | BC18: =IF(OR(AJ18<>"ניתוח",AX18=""),"",IF(AX18<=30,1,0)) -> 1 | BD18: =IF(OR(AG18="",AI18="",AJ18<>"ניתוח"),"",AI18-AG18) -> 17 | BE18: =IF(OR(AH18="",AI18="",AND(AJ18<>"הקרנות",AJ18<>"כימו-הקרנות")),"",AI18-AH18) | BF18: =IF(OR(AJ18<>"ניתוח",AI18="",AN18=""),"",AN18-AI18) -> 17 | BG18: =IF(OR(AJ18<>"ניתוח",AI18="",AO18=""),"",AO18-AI18) | BH18: =IF(BG18="","",IF(BG18<=42,1,0))
A19: =IF(OR(B19="",C19="",D19="",Z19=""),"","ENT-"&RIGHT(YEAR(Z19),2)&"-"&TEXT(B19,"000")&"-"&C19&"-"&D19&"-"&TEXT(MONTH(Z19),"00")) -> ENT-26-014-NPC-M-06 | B19: 14 | C19: NPC | D19: M | G19: 58 | H19: נ | I19: 0 | P19: T3 | Q19: N1 | R19: M0 | S19: III | T19: לא רלוונטי | Z19: 46185 | AC19: 46198 | AD19: 46198 | AE19: כימו-הקרנות | AH19: 46199 | AI19: 46237 | AJ19: כימו-הקרנות | AP19: כן | AQ19: לא | AR19: =IF(A19="","",COUNTIF(MDT!$B$5:$B$104,A19)) -> 1 | AS19: =IF(A19="","",COUNTIFS(MDT!$B$5:$B$104,A19,MDT!$E$5:$E$104,"נדחה — מידע חסר")) -> 0 | AV19: =IF(OR(X19="",Z19=""),"",Z19-X19) | AW19: =IF(OR(Z19="",AC19=""),"",AC19-Z19) -> 13 | AX19: =IF(OR(AD19="",AI19=""),"",AI19-AD19) -> 39 | AY19: =IF(OR(Z19="",AI19=""),"",AI19-Z19) -> 52 | AZ19: =IF(AY19="","",IF(AY19<=30,1,0)) -> 0 | BA19: =IF(AY19="","",IF(AY19>60,1,0)) -> 0 | BB19: =IF(AY19="","",IF(AY19>67,1,0)) -> 0 | BC19: =IF(OR(AJ19<>"ניתוח",AX19=""),"",IF(AX19<=30,1,0)) | BD19: =IF(OR(AG19="",AI19="",AJ19<>"ניתוח"),"",AI19-AG19) | BE19: =IF(OR(AH19="",AI19="",AND(AJ19<>"הקרנות",AJ19<>"כימו-הקרנות")),"",AI19-AH19) -> 38 | BF19: =IF(OR(AJ19<>"ניתוח",AI19="",AN19=""),"",AN19-AI19) | BG19: =IF(OR(AJ19<>"ניתוח",AI19="",AO19=""),"",AO19-AI19) | BH19: =IF(BG19="","",IF(BG19<=42,1,0))
A20: =IF(OR(B20="",C20="",D20="",Z20=""),"","ENT-"&RIGHT(YEAR(Z20),2)&"-"&TEXT(B20,"000")&"-"&C20&"-"&D20&"-"&TEXT(MONTH(Z20),"00")) -> ENT-26-015-TON-R-06 | B20: 15 | C20: TON | D20: R | G20: 59 | H20: ז | I20: 0 | P20: T1 | Q20: N1 | R20: M0 | S20: I | T20: חיובי | Z20: 46188 | AC20: 46198 | AD20: 46198 | AE20: ניתוח | AG20: 46199 | AI20: 46215 | AJ20: ניתוח | AP20: לא | AQ20: לא | AR20: =IF(A20="","",COUNTIF(MDT!$B$5:$B$104,A20)) -> 1 | AS20: =IF(A20="","",COUNTIFS(MDT!$B$5:$B$104,A20,MDT!$E$5:$E$104,"נדחה — מידע חסר")) -> 0 | AV20: =IF(OR(X20="",Z20=""),"",Z20-X20) | AW20: =IF(OR(Z20="",AC20=""),"",AC20-Z20) -> 10 | AX20: =IF(OR(AD20="",AI20=""),"",AI20-AD20) -> 17 | AY20: =IF(OR(Z20="",AI20=""),"",AI20-Z20) -> 27 | AZ20: =IF(AY20="","",IF(AY20<=30,1,0)) -> 1 | BA20: =IF(AY20="","",IF(AY20>60,1,0)) -> 0 | BB20: =IF(AY20="","",IF(AY20>67,1,0)) -> 0 | BC20: =IF(OR(AJ20<>"ניתוח",AX20=""),"",IF(AX20<=30,1,0)) -> 1 | BD20: =IF(OR(AG20="",AI20="",AJ20<>"ניתוח"),"",AI20-AG20) -> 16 | BE20: =IF(OR(AH20="",AI20="",AND(AJ20<>"הקרנות",AJ20<>"כימו-הקרנות")),"",AI20-AH20) | BF20: =IF(OR(AJ20<>"ניתוח",AI20="",AN20=""),"",AN20-AI20) | BG20: =IF(OR(AJ20<>"ניתוח",AI20="",AO20=""),"",AO20-AI20) | BH20: =IF(BG20="","",IF(BG20<=42,1,0))
A21: =IF(OR(B21="",C21="",D21="",Z21=""),"","ENT-"&RIGHT(YEAR(Z21),2)&"-"&TEXT(B21,"000")&"-"&C21&"-"&D21&"-"&TEXT(MONTH(Z21),"00")) -> ENT-26-016-SGL-M-06 | B21: 16 | C21: SGL | D21: M | G21: 74 | H21: ז | I21: 1 | P21: T3 | Q21: N2c | R21: M0 | S21: IVA | T21: לא רלוונטי | Z21: 46188 | AC21: 46205 | AD21: 46205 | AE21: כימו-הקרנות | AH21: 46206 | AI21: 46251 | AJ21: כימו-הקרנות | AP21: כן | AQ21: כן | AR21: =IF(A21="","",COUNTIF(MDT!$B$5:$B$104,A21)) -> 1 | AS21: =IF(A21="","",COUNTIFS(MDT!$B$5:$B$104,A21,MDT!$E$5:$E$104,"נדחה — מידע חסר")) -> 0 | AV21: =IF(OR(X21="",Z21=""),"",Z21-X21) | AW21: =IF(OR(Z21="",AC21=""),"",AC21-Z21) -> 17 | AX21: =IF(OR(AD21="",AI21=""),"",AI21-AD21) -> 46 | AY21: =IF(OR(Z21="",AI21=""),"",AI21-Z21) -> 63 | AZ21: =IF(AY21="","",IF(AY21<=30,1,0)) -> 0 | BA21: =IF(AY21="","",IF(AY21>60,1,0)) -> 1 | BB21: =IF(AY21="","",IF(AY21>67,1,0)) -> 0 | BC21: =IF(OR(AJ21<>"ניתוח",AX21=""),"",IF(AX21<=30,1,0)) | BD21: =IF(OR(AG21="",AI21="",AJ21<>"ניתוח"),"",AI21-AG21) | BE21: =IF(OR(AH21="",AI21="",AND(AJ21<>"הקרנות",AJ21<>"כימו-הקרנות")),"",AI21-AH21) -> 45 | BF21: =IF(OR(AJ21<>"ניתוח",AI21="",AN21=""),"",AN21-AI21) | BG21: =IF(OR(AJ21<>"ניתוח",AI21="",AO21=""),"",AO21-AI21) | BH21: =IF(BG21="","",IF(BG21<=42,1,0))
A22: =IF(OR(B22="",C22="",D22="",Z22=""),"","ENT-"&RIGHT(YEAR(Z22),2)&"-"&TEXT(B22,"000")&"-"&C22&"-"&D22&"-"&TEXT(MONTH(Z22),"00")) -> ENT-26-017-SNC-L-06 | B22: 17 | C22: SNC | D22: L | G22: 66 | H22: נ | I22: 1 | P22: T3 | Q22: N0 | R22: M0 | S22: III | T22: לא רלוונטי | Z22: 46190 | AC22: 46205 | AD22: 46205 | AE22: ניתוח | AG22: 46206 | AI22: 46234 | AJ22: ניתוח | AP22: לא | AQ22: לא | AR22: =IF(A22="","",COUNTIF(MDT!$B$5:$B$104,A22)) -> 1 | AS22: =IF(A22="","",COUNTIFS(MDT!$B$5:$B$104,A22,MDT!$E$5:$E$104,"נדחה — מידע חסר")) -> 0 | AV22: =IF(OR(X22="",Z22=""),"",Z22-X22) | AW22: =IF(OR(Z22="",AC22=""),"",AC22-Z22) -> 15 | AX22: =IF(OR(AD22="",AI22=""),"",AI22-AD22) -> 29 | AY22: =IF(OR(Z22="",AI22=""),"",AI22-Z22) -> 44 | AZ22: =IF(AY22="","",IF(AY22<=30,1,0)) -> 0 | BA22: =IF(AY22="","",IF(AY22>60,1,0)) -> 0 | BB22: =IF(AY22="","",IF(AY22>67,1,0)) -> 0 | BC22: =IF(OR(AJ22<>"ניתוח",AX22=""),"",IF(AX22<=30,1,0)) -> 1 | BD22: =IF(OR(AG22="",AI22="",AJ22<>"ניתוח"),"",AI22-AG22) -> 28 | BE22: =IF(OR(AH22="",AI22="",AND(AJ22<>"הקרנות",AJ22<>"כימו-הקרנות")),"",AI22-AH22) | BF22: =IF(OR(AJ22<>"ניתוח",AI22="",AN22=""),"",AN22-AI22) | BG22: =IF(OR(AJ22<>"ניתוח",AI22="",AO22=""),"",AO22-AI22) | BH22: =IF(BG22="","",IF(BG22<=42,1,0))
A23: =IF(OR(B23="",C23="",D23="",Z23=""),"","ENT-"&RIGHT(YEAR(Z23),2)&"-"&TEXT(B23,"000")&"-"&C23&"-"&D23&"-"&TEXT(MONTH(Z23),"00")) -> ENT-26-018-BOT-R-06 | B23: 18 | C23: BOT | D23: R | G23: 45 | H23: נ | I23: 0 | P23: T3 | Q23: N2b | R23: M0 | S23: IVA | T23: שלילי | Z23: 46191 | AC23: 46205 | AD23: 46205 | AE23: כימו-הקרנות | AH23: 46206 | AI23: 46232 | AJ23: כימו-הקרנות | AP23: לא | AQ23: לא | AR23: =IF(A23="","",COUNTIF(MDT!$B$5:$B$104,A23)) -> 1 | AS23: =IF(A23="","",COUNTIFS(MDT!$B$5:$B$104,A23,MDT!$E$5:$E$104,"נדחה — מידע חסר")) -> 0 | AV23: =IF(OR(X23="",Z23=""),"",Z23-X23) | AW23: =IF(OR(Z23="",AC23=""),"",AC23-Z23) -> 14 | AX23: =IF(OR(AD23="",AI23=""),"",AI23-AD23) -> 27 | AY23: =IF(OR(Z23="",AI23=""),"",AI23-Z23) -> 41 | AZ23: =IF(AY23="","",IF(AY23<=30,1,0)) -> 0 | BA23: =IF(AY23="","",IF(AY23>60,1,0)) -> 0 | BB23: =IF(AY23="","",IF(AY23>67,1,0)) -> 0 | BC23: =IF(OR(AJ23<>"ניתוח",AX23=""),"",IF(AX23<=30,1,0)) | BD23: =IF(OR(AG23="",AI23="",AJ23<>"ניתוח"),"",AI23-AG23) | BE23: =IF(OR(AH23="",AI23="",AND(AJ23<>"הקרנות",AJ23<>"כימו-הקרנות")),"",AI23-AH23) -> 26 | BF23: =IF(OR(AJ23<>"ניתוח",AI23="",AN23=""),"",AN23-AI23) | BG23: =IF(OR(AJ23<>"ניתוח",AI23="",AO23=""),"",AO23-AI23) | BH23: =IF(BG23="","",IF(BG23<=42,1,0))
A24: =IF(OR(B24="",C24="",D24="",Z24=""),"","ENT-"&RIGHT(YEAR(Z24),2)&"-"&TEXT(B24,"000")&"-"&C24&"-"&D24&"-"&TEXT(MONTH(Z24),"00")) -> ENT-26-019-GUM-R-06 | B24: 19 | C24: GUM | D24: R | G24: 70 | H24: ז | I24: 1 | P24: T4a | Q24: N0 | R24: M0 | S24: IVA | T24: לא רלוונטי | Z24: 46192 | AC24: 46205 | AD24: 46205 | AE24: ניתוח | AG24: 46206 | AI24: 46223 | AJ24: ניתוח | AP24: כן | AQ24: לא | AR24: =IF(A24="","",COUNTIF(MDT!$B$5:$B$104,A24)) -> 1 | AS24: =IF(A24="","",COUNTIFS(MDT!$B$5:$B$104,A24,MDT!$E$5:$E$104,"נדחה — מידע חסר")) -> 0 | AV24: =IF(OR(X24="",Z24=""),"",Z24-X24) | AW24: =IF(OR(Z24="",AC24=""),"",AC24-Z24) -> 13 | AX24: =IF(OR(AD24="",AI24=""),"",AI24-AD24) -> 18 | AY24: =IF(OR(Z24="",AI24=""),"",AI24-Z24) -> 31 | AZ24: =IF(AY24="","",IF(AY24<=30,1,0)) -> 0 | BA24: =IF(AY24="","",IF(AY24>60,1,0)) -> 0 | BB24: =IF(AY24="","",IF(AY24>67,1,0)) -> 0 | BC24: =IF(OR(AJ24<>"ניתוח",AX24=""),"",IF(AX24<=30,1,0)) -> 1 | BD24: =IF(OR(AG24="",AI24="",AJ24<>"ניתוח"),"",AI24-AG24) -> 17 | BE24: =IF(OR(AH24="",AI24="",AND(AJ24<>"הקרנות",AJ24<>"כימו-הקרנות")),"",AI24-AH24) | BF24: =IF(OR(AJ24<>"ניתוח",AI24="",AN24=""),"",AN24-AI24) | BG24: =IF(OR(AJ24<>"ניתוח",AI24="",AO24=""),"",AO24-AI24) | BH24: =IF(BG24="","",IF(BG24<=42,1,0))
A25: =IF(OR(B25="",C25="",D25="",Z25=""),"","ENT-"&RIGHT(YEAR(Z25),2)&"-"&TEXT(B25,"000")&"-"&C25&"-"&D25&"-"&TEXT(MONTH(Z25),"00")) -> ENT-26-020-SGL-M-06 | B25: 20 | C25: SGL | D25: M | G25: 55 | H25: נ | I25: 0 | P25: T2 | Q25: N0 | R25: M0 | S25: II | T25: לא רלוונטי | Z25: 46195 | AC25: 46205 | AD25: 46205 | AE25: ניתוח | AG25: 46206 | AI25: 46219 | AJ25: ניתוח | AP25: לא | AQ25: לא | AR25: =IF(A25="","",COUNTIF(MDT!$B$5:$B$104,A25)) -> 1 | AS25: =IF(A25="","",COUNTIFS(MDT!$B$5:$B$104,A25,MDT!$E$5:$E$104,"נדחה — מידע חסר")) -> 0 | AV25: =IF(OR(X25="",Z25=""),"",Z25-X25) | AW25: =IF(OR(Z25="",AC25=""),"",AC25-Z25) -> 10 | AX25: =IF(OR(AD25="",AI25=""),"",AI25-AD25) -> 14 | AY25: =IF(OR(Z25="",AI25=""),"",AI25-Z25) -> 24 | AZ25: =IF(AY25="","",IF(AY25<=30,1,0)) -> 1 | BA25: =IF(AY25="","",IF(AY25>60,1,0)) -> 0 | BB25: =IF(AY25="","",IF(AY25>67,1,0)) -> 0 | BC25: =IF(OR(AJ25<>"ניתוח",AX25=""),"",IF(AX25<=30,1,0)) -> 1 | BD25: =IF(OR(AG25="",AI25="",AJ25<>"ניתוח"),"",AI25-AG25) -> 13 | BE25: =IF(OR(AH25="",AI25="",AND(AJ25<>"הקרנות",AJ25<>"כימו-הקרנות")),"",AI25-AH25) | BF25: =IF(OR(AJ25<>"ניתוח",AI25="",AN25=""),"",AN25-AI25) | BG25: =IF(OR(AJ25<>"ניתוח",AI25="",AO25=""),"",AO25-AI25) | BH25: =IF(BG25="","",IF(BG25<=42,1,0))

Sheet Historical
A1: מאגר מטופלים קיים — בקרה היסטורית (12 החודשים שקדמו להפעלה) | H1: צהוב = להזנה · אפור = מחושב אוטומטית · כחול = שורת דוגמה סינתטית (אינה נספרת)
A2: זיהוי | E2: כניסה | G2: דמוגרפיה | O2: גידול | X2: מועדים | AG2: קיבולת | AI2: מועדים | AM2: הצגה חוזרת | AP2: גורמי עיכוב | AR2: תהליך | AV2: מרווחים (ימים) | BI2: הערות
A3: מספר מחקר (ת״ז מחקרית) | B3: מספר רץ | C3: קוד אתר | D3: צד | E3: תאריך הסכמה מדעת | F3: סטטוס במחקר | G3: גיל באבחנה | H3: מין | I3: ECOG | J3: עישון | K3: שנות קופסה | L3: אלכוהול | M3: מחלות רקע (ACE-27) | N3: מרחק מגורים | O3: היסטולוגיה | P3: cT | Q3: cN | R3: cM | S3: שלב קליני | T3: p16 / HPV | U3: EBV | V3: pT | W3: pN | X3: ייעוץ ראשון אא״ג | Y3: ביופסיה | Z3: דוח פתולוגיה ממאירה (t = 0) | AA3: הדמיית שלב CT / MRI | AB3: PET-CT | AC3: הצגה ראשונה בוועדה | AD3: החלטת ועדה | AE3: מודאליות מתוכננת | AF3: אתר טיפול | AG3: הפניה לחדר ניתוח | AH3: הפניה למכון ההקרנות | AI3: תחילת טיפול מכריע ראשון | AJ3: מודאליות בפועל | AK3: תואם החלטת ועדה | AL3: סיבת אי-התאמה | AM3: הצגה חוזרת בוועדה | AN3: החלטה שנייה | AO3: תחילת טיפול משלים | AP3: נדרשה הערכה דנטלית | AQ3: PEG מניעתי | AR3: מספר הצגות בוועדה | AS3: דחיות בשל מידע חסר | AT3: סגירת מעקב | AU3: סגר את המעקב | AV3: ייעוץ ← פתולוגיה | AW3: פתולוגיה ← ועדה | AX3: החלטה ← טיפול | AY3: פתולוגיה ← טיפול · תוצא ראשוני | AZ3: עד 30 יום | BA3: מעל 60 יום | BB3: מעל 67 יום | BC3: ניתוח ≤30 יום מההחלטה (חוזר 1/2020) | BD3: הפניה ← ניתוח | BE3: הפניה ← הקרנות | BF3: ניתוח ← החלטה שנייה | BG3: ניתוח ← טיפול משלים | BH3: משלים ≤42 יום | BI3: הערות (ללא פרטים מזהים)
A4: id | B4: seq | C4: site | D4: side | E4: consent | F4: status | G4: age | H4: sex | I4: ecog | J4: smoke | K4: py | L4: alc | M4: ace | N4: dist | O4: hist | P4: cT | Q4: cN | R4: cM | S4: stage | T4: p16 | U4: ebv | V4: pT | W4: pN | X4: consult | Y4: biopsy | Z4: t0 | AA4: ct | AB4: pet | AC4: mdt1 | AD4: dec | AE4: pmod | AF4: txsite | AG4: orref | AH4: rtref | AI4: tx | AJ4: amod | AK4: conc | AL4: ncr | AM4: mdt2 | AN4: dec2 | AO4: adj | AP4: dental | AQ4: peg | AR4: nres | AS4: ndef | AT4: close | AU4: closer | AV4: i_cp | AW4: i_pm | AX4: i_dt | AY4: i_pt | AZ4: f30 | BA4: f60 | BB4: f67 | BC4: moh | BD4: i_or | BE4: i_rt | BF4: i_s2 | BG4: i_adj | BH4: f42 | BI4: note
A5: =IF(OR(B5="",C5="",D5="",Z5=""),"","HIS-"&RIGHT(YEAR(Z5),2)&"-"&TEXT(B5,"000")&"-"&C5&"-"&D5&"-"&TEXT(MONTH(Z5),"00")) -> HIS-26-000-NPC-M-09 | B5: 0 | C5: NPC | D5: M | E5: לא רלוונטי | F5: פעיל | G5: 54 | H5: ז | I5: 1 | J5: עישן בעבר | K5: 20 | L5: מתון | M5: 1 — קל | N5: 10–30 ק״מ | O5: Nasopharyngeal carcinoma (WHO) | P5: T2 | Q5: N2 | R5: M0 | S5: III | T5: לא רלוונטי | U5: חיובי | X5: 46264 | Y5: 46268 | Z5: 46275 | AA5: 46279 | AB5: 46286 | AC5: 46289 | AD5: 46289 | AE5: כימו-הקרנות | AF5: דוידוף | AH5: 46290 | AI5: 46315 | AJ5: כימו-הקרנות | AK5: כן | AP5: כן | AQ5: לא | AR5: =IF(A5="","",COUNTIF(MDT!$B$5:$B$104,A5)) -> 0 | AS5: =IF(A5="","",COUNTIFS(MDT!$B$5:$B$104,A5,MDT!$E$5:$E$104,"נדחה — מידע חסר")) -> 0 | AT5: 46315 | AU5: מנהל תחום אא״ג | AV5: =IF(OR(X5="",Z5=""),"",Z5-X5) -> 11 | AW5: =IF(OR(Z5="",AC5=""),"",AC5-Z5) -> 14 | AX5: =IF(OR(AD5="",AI5=""),"",AI5-AD5) -> 26 | AY5: =IF(OR(Z5="",AI5=""),"",AI5-Z5) -> 40 | AZ5: =IF(AY5="","",IF(AY5<=30,1,0)) -> 0 | BA5: =IF(AY5="","",IF(AY5>60,1,0)) -> 0 | BB5: =IF(AY5="","",IF(AY5>67,1,0)) -> 0 | BC5: =IF(OR(AJ5<>"ניתוח",AX5=""),"",IF(AX5<=30,1,0)) | BD5: =IF(OR(AG5="",AI5="",AJ5<>"ניתוח"),"",AI5-AG5) | BE5: =IF(OR(AH5="",AI5="",AND(AJ5<>"הקרנות",AJ5<>"כימו-הקרנות")),"",AI5-AH5) -> 25 | BF5: =IF(OR(AJ5<>"ניתוח",AI5="",AN5=""),"",AN5-AI5) | BG5: =IF(OR(AJ5<>"ניתוח",AI5="",AO5=""),"",AO5-AI5) | BH5: =IF(BG5="","",IF(BG5<=42,1,0)) | BI5: שורת דוגמה סינתטית — ENT-26-000-NPC-M-09
A6: =IF(OR(B6="",C6="",D6="",Z6=""),"","HIS-"&RIGHT(YEAR(Z6),2)&"-"&TEXT(B6,"000")&"-"&C6&"-"&D6&"-"&TEXT(MONTH(Z6),"00")) | B6: 1 | E6: לא רלוונטי | AR6: =IF(A6="","",COUNTIF(MDT!$B$5:$B$104,A6)) | AS6: =IF(A6="","",COUNTIFS(MDT!$B$5:$B$104,A6,MDT!$E$5:$E$104,"נדחה — מידע חסר")) | AV6: =IF(OR(X6="",Z6=""),"",Z6-X6) | AW6: =IF(OR(Z6="",AC6=""),"",AC6-Z6) | AX6: =IF(OR(AD6="",AI6=""),"",AI6-AD6) | AY6: =IF(OR(Z6="",AI6=""),"",AI6-Z6) | AZ6: =IF(AY6="","",IF(AY6<=30,1,0)) | BA6: =IF(AY6="","",IF(AY6>60,1,0)) | BB6: =IF(AY6="","",IF(AY6>67,1,0)) | BC6: =IF(OR(AJ6<>"ניתוח",AX6=""),"",IF(AX6<=30,1,0)) | BD6: =IF(OR(AG6="",AI6="",AJ6<>"ניתוח"),"",AI6-AG6) | BE6: =IF(OR(AH6="",AI6="",AND(AJ6<>"הקרנות",AJ6<>"כימו-הקרנות")),"",AI6-AH6) | BF6: =IF(OR(AJ6<>"ניתוח",AI6="",AN6=""),"",AN6-AI6) | BG6: =IF(OR(AJ6<>"ניתוח",AI6="",AO6=""),"",AO6-AI6) | BH6: =IF(BG6="","",IF(BG6<=42,1,0))
A7: =IF(OR(B7="",C7="",D7="",Z7=""),"","HIS-"&RIGHT(YEAR(Z7),2)&"-"&TEXT(B7,"000")&"-"&C7&"-"&D7&"-"&TEXT(MONTH(Z7),"00")) | B7: 2 | E7: לא רלוונטי | AR7: =IF(A7="","",COUNTIF(MDT!$B$5:$B$104,A7)) | AS7: =IF(A7="","",COUNTIFS(MDT!$B$5:$B$104,A7,MDT!$E$5:$E$104,"נדחה — מידע חסר")) | AV7: =IF(OR(X7="",Z7=""),"",Z7-X7) | AW7: =IF(OR(Z7="",AC7=""),"",AC7-Z7) | AX7: =IF(OR(AD7="",AI7=""),"",AI7-AD7) | AY7: =IF(OR(Z7="",AI7=""),"",AI7-Z7) | AZ7: =IF(AY7="","",IF(AY7<=30,1,0)) | BA7: =IF(AY7="","",IF(AY7>60,1,0)) | BB7: =IF(AY7="","",IF(AY7>67,1,0)) | BC7: =IF(OR(AJ7<>"ניתוח",AX7=""),"",IF(AX7<=30,1,0)) | BD7: =IF(OR(AG7="",AI7="",AJ7<>"ניתוח"),"",AI7-AG7) | BE7: =IF(OR(AH7="",AI7="",AND(AJ7<>"הקרנות",AJ7<>"כימו-הקרנות")),"",AI7-AH7) | BF7: =IF(OR(AJ7<>"ניתוח",AI7="",AN7=""),"",AN7-AI7) | BG7: =IF(OR(AJ7<>"ניתוח",AI7="",AO7=""),"",AO7-AI7) | BH7: =IF(BG7="","",IF(BG7<=42,1,0))
A8: =IF(OR(B8="",C8="",D8="",Z8=""),"","HIS-"&RIGHT(YEAR(Z8),2)&"-"&TEXT(B8,"000")&"-"&C8&"-"&D8&"-"&TEXT(MONTH(Z8),"00")) | B8: 3 | E8: לא רלוונטי | AR8: =IF(A8="","",COUNTIF(MDT!$B$5:$B$104,A8)) | AS8: =IF(A8="","",COUNTIFS(MDT!$B$5:$B$104,A8,MDT!$E$5:$E$104,"נדחה — מידע חסר")) | AV8: =IF(OR(X8="",Z8=""),"",Z8-X8) | AW8: =IF(OR(Z8="",AC8=""),"",AC8-Z8) | AX8: =IF(OR(AD8="",AI8=""),"",AI8-AD8) | AY8: =IF(OR(Z8="",AI8=""),"",AI8-Z8) | AZ8: =IF(AY8="","",IF(AY8<=30,1,0)) | BA8: =IF(AY8="","",IF(AY8>60,1,0)) | BB8: =IF(AY8="","",IF(AY8>67,1,0)) | BC8: =IF(OR(AJ8<>"ניתוח",AX8=""),"",IF(AX8<=30,1,0)) | BD8: =IF(OR(AG8="",AI8="",AJ8<>"ניתוח"),"",AI8-AG8) | BE8: =IF(OR(AH8="",AI8="",AND(AJ8<>"הקרנות",AJ8<>"כימו-הקרנות")),"",AI8-AH8) | BF8: =IF(OR(AJ8<>"ניתוח",AI8="",AN8=""),"",AN8-AI8) | BG8: =IF(OR(AJ8<>"ניתוח",AI8="",AO8=""),"",AO8-AI8) | BH8: =IF(BG8="","",IF(BG8<=42,1,0))
A9: =IF(OR(B9="",C9="",D9="",Z9=""),"","HIS-"&RIGHT(YEAR(Z9),2)&"-"&TEXT(B9,"000")&"-"&C9&"-"&D9&"-"&TEXT(MONTH(Z9),"00")) | B9: 4 | E9: לא רלוונטי | AR9: =IF(A9="","",COUNTIF(MDT!$B$5:$B$104,A9)) | AS9: =IF(A9="","",COUNTIFS(MDT!$B$5:$B$104,A9,MDT!$E$5:$E$104,"נדחה — מידע חסר")) | AV9: =IF(OR(X9="",Z9=""),"",Z9-X9) | AW9: =IF(OR(Z9="",AC9=""),"",AC9-Z9) | AX9: =IF(OR(AD9="",AI9=""),"",AI9-AD9) | AY9: =IF(OR(Z9="",AI9=""),"",AI9-Z9) | AZ9: =IF(AY9="","",IF(AY9<=30,1,0)) | BA9: =IF(AY9="","",IF(AY9>60,1,0)) | BB9: =IF(AY9="","",IF(AY9>67,1,0)) | BC9: =IF(OR(AJ9<>"ניתוח",AX9=""),"",IF(AX9<=30,1,0)) | BD9: =IF(OR(AG9="",AI9="",AJ9<>"ניתוח"),"",AI9-AG9) | BE9: =IF(OR(AH9="",AI9="",AND(AJ9<>"הקרנות",AJ9<>"כימו-הקרנות")),"",AI9-AH9) | BF9: =IF(OR(AJ9<>"ניתוח",AI9="",AN9=""),"",AN9-AI9) | BG9: =IF(OR(AJ9<>"ניתוח",AI9="",AO9=""),"",AO9-AI9) | BH9: =IF(BG9="","",IF(BG9<=42,1,0))
A10: =IF(OR(B10="",C10="",D10="",Z10=""),"","HIS-"&RIGHT(YEAR(Z10),2)&"-"&TEXT(B10,"000")&"-"&C10&"-"&D10&"-"&TEXT(MONTH(Z10),"00")) | B10: 5 | E10: לא רלוונטי | AR10: =IF(A10="","",COUNTIF(MDT!$B$5:$B$104,A10)) | AS10: =IF(A10="","",COUNTIFS(MDT!$B$5:$B$104,A10,MDT!$E$5:$E$104,"נדחה — מידע חסר")) | AV10: =IF(OR(X10="",Z10=""),"",Z10-X10) | AW10: =IF(OR(Z10="",AC10=""),"",AC10-Z10) | AX10: =IF(OR(AD10="",AI10=""),"",AI10-AD10) | AY10: =IF(OR(Z10="",AI10=""),"",AI10-Z10) | AZ10: =IF(AY10="","",IF(AY10<=30,1,0)) | BA10: =IF(AY10="","",IF(AY10>60,1,0)) | BB10: =IF(AY10="","",IF(AY10>67,1,0)) | BC10: =IF(OR(AJ10<>"ניתוח",AX10=""),"",IF(AX10<=30,1,0)) | BD10: =IF(OR(AG10="",AI10="",AJ10<>"ניתוח"),"",AI10-AG10) | BE10: =IF(OR(AH10="",AI10="",AND(AJ10<>"הקרנות",AJ10<>"כימו-הקרנות")),"",AI10-AH10) | BF10: =IF(OR(AJ10<>"ניתוח",AI10="",AN10=""),"",AN10-AI10) | BG10: =IF(OR(AJ10<>"ניתוח",AI10="",AO10=""),"",AO10-AI10) | BH10: =IF(BG10="","",IF(BG10<=42,1,0))
A11: =IF(OR(B11="",C11="",D11="",Z11=""),"","HIS-"&RIGHT(YEAR(Z11),2)&"-"&TEXT(B11,"000")&"-"&C11&"-"&D11&"-"&TEXT(MONTH(Z11),"00")) | B11: 6 | E11: לא רלוונטי | AR11: =IF(A11="","",COUNTIF(MDT!$B$5:$B$104,A11)) | AS11: =IF(A11="","",COUNTIFS(MDT!$B$5:$B$104,A11,MDT!$E$5:$E$104,"נדחה — מידע חסר")) | AV11: =IF(OR(X11="",Z11=""),"",Z11-X11) | AW11: =IF(OR(Z11="",AC11=""),"",AC11-Z11) | AX11: =IF(OR(AD11="",AI11=""),"",AI11-AD11) | AY11: =IF(OR(Z11="",AI11=""),"",AI11-Z11) | AZ11: =IF(AY11="","",IF(AY11<=30,1,0)) | BA11: =IF(AY11="","",IF(AY11>60,1,0)) | BB11: =IF(AY11="","",IF(AY11>67,1,0)) | BC11: =IF(OR(AJ11<>"ניתוח",AX11=""),"",IF(AX11<=30,1,0)) | BD11: =IF(OR(AG11="",AI11="",AJ11<>"ניתוח"),"",AI11-AG11) | BE11: =IF(OR(AH11="",AI11="",AND(AJ11<>"הקרנות",AJ11<>"כימו-הקרנות")),"",AI11-AH11) | BF11: =IF(OR(AJ11<>"ניתוח",AI11="",AN11=""),"",AN11-AI11) | BG11: =IF(OR(AJ11<>"ניתוח",AI11="",AO11=""),"",AO11-AI11) | BH11: =IF(BG11="","",IF(BG11<=42,1,0))
A12: =IF(OR(B12="",C12="",D12="",Z12=""),"","HIS-"&RIGHT(YEAR(Z12),2)&"-"&TEXT(B12,"000")&"-"&C12&"-"&D12&"-"&TEXT(MONTH(Z12),"00")) | B12: 7 | E12: לא רלוונטי | AR12: =IF(A12="","",COUNTIF(MDT!$B$5:$B$104,A12)) | AS12: =IF(A12="","",COUNTIFS(MDT!$B$5:$B$104,A12,MDT!$E$5:$E$104,"נדחה — מידע חסר")) | AV12: =IF(OR(X12="",Z12=""),"",Z12-X12) | AW12: =IF(OR(Z12="",AC12=""),"",AC12-Z12) | AX12: =IF(OR(AD12="",AI12=""),"",AI12-AD12) | AY12: =IF(OR(Z12="",AI12=""),"",AI12-Z12) | AZ12: =IF(AY12="","",IF(AY12<=30,1,0)) | BA12: =IF(AY12="","",IF(AY12>60,1,0)) | BB12: =IF(AY12="","",IF(AY12>67,1,0)) | BC12: =IF(OR(AJ12<>"ניתוח",AX12=""),"",IF(AX12<=30,1,0)) | BD12: =IF(OR(AG12="",AI12="",AJ12<>"ניתוח"),"",AI12-AG12) | BE12: =IF(OR(AH12="",AI12="",AND(AJ12<>"הקרנות",AJ12<>"כימו-הקרנות")),"",AI12-AH12) | BF12: =IF(OR(AJ12<>"ניתוח",AI12="",AN12=""),"",AN12-AI12) | BG12: =IF(OR(AJ12<>"ניתוח",AI12="",AO12=""),"",AO12-AI12) | BH12: =IF(BG12="","",IF(BG12<=42,1,0))
A13: =IF(OR(B13="",C13="",D13="",Z13=""),"","HIS-"&RIGHT(YEAR(Z13),2)&"-"&TEXT(B13,"000")&"-"&C13&"-"&D13&"-"&TEXT(MONTH(Z13),"00")) | B13: 8 | E13: לא רלוונטי | AR13: =IF(A13="","",COUNTIF(MDT!$B$5:$B$104,A13)) | AS13: =IF(A13="","",COUNTIFS(MDT!$B$5:$B$104,A13,MDT!$E$5:$E$104,"נדחה — מידע חסר")) | AV13: =IF(OR(X13="",Z13=""),"",Z13-X13) | AW13: =IF(OR(Z13="",AC13=""),"",AC13-Z13) | AX13: =IF(OR(AD13="",AI13=""),"",AI13-AD13) | AY13: =IF(OR(Z13="",AI13=""),"",AI13-Z13) | AZ13: =IF(AY13="","",IF(AY13<=30,1,0)) | BA13: =IF(AY13="","",IF(AY13>60,1,0)) | BB13: =IF(AY13="","",IF(AY13>67,1,0)) | BC13: =IF(OR(AJ13<>"ניתוח",AX13=""),"",IF(AX13<=30,1,0)) | BD13: =IF(OR(AG13="",AI13="",AJ13<>"ניתוח"),"",AI13-AG13) | BE13: =IF(OR(AH13="",AI13="",AND(AJ13<>"הקרנות",AJ13<>"כימו-הקרנות")),"",AI13-AH13) | BF13: =IF(OR(AJ13<>"ניתוח",AI13="",AN13=""),"",AN13-AI13) | BG13: =IF(OR(AJ13<>"ניתוח",AI13="",AO13=""),"",AO13-AI13) | BH13: =IF(BG13="","",IF(BG13<=42,1,0))
A14: =IF(OR(B14="",C14="",D14="",Z14=""),"","HIS-"&RIGHT(YEAR(Z14),2)&"-"&TEXT(B14,"000")&"-"&C14&"-"&D14&"-"&TEXT(MONTH(Z14),"00")) | B14: 9 | E14: לא רלוונטי | AR14: =IF(A14="","",COUNTIF(MDT!$B$5:$B$104,A14)) | AS14: =IF(A14="","",COUNTIFS(MDT!$B$5:$B$104,A14,MDT!$E$5:$E$104,"נדחה — מידע חסר")) | AV14: =IF(OR(X14="",Z14=""),"",Z14-X14) | AW14: =IF(OR(Z14="",AC14=""),"",AC14-Z14) | AX14: =IF(OR(AD14="",AI14=""),"",AI14-AD14) | AY14: =IF(OR(Z14="",AI14=""),"",AI14-Z14) | AZ14: =IF(AY14="","",IF(AY14<=30,1,0)) | BA14: =IF(AY14="","",IF(AY14>60,1,0)) | BB14: =IF(AY14="","",IF(AY14>67,1,0)) | BC14: =IF(OR(AJ14<>"ניתוח",AX14=""),"",IF(AX14<=30,1,0)) | BD14: =IF(OR(AG14="",AI14="",AJ14<>"ניתוח"),"",AI14-AG14) | BE14: =IF(OR(AH14="",AI14="",AND(AJ14<>"הקרנות",AJ14<>"כימו-הקרנות")),"",AI14-AH14) | BF14: =IF(OR(AJ14<>"ניתוח",AI14="",AN14=""),"",AN14-AI14) | BG14: =IF(OR(AJ14<>"ניתוח",AI14="",AO14=""),"",AO14-AI14) | BH14: =IF(BG14="","",IF(BG14<=42,1,0))
A15: =IF(OR(B15="",C15="",D15="",Z15=""),"","HIS-"&RIGHT(YEAR(Z15),2)&"-"&TEXT(B15,"000")&"-"&C15&"-"&D15&"-"&TEXT(MONTH(Z15),"00")) | B15: 10 | E15: לא רלוונטי | AR15: =IF(A15="","",COUNTIF(MDT!$B$5:$B$104,A15)) | AS15: =IF(A15="","",COUNTIFS(MDT!$B$5:$B$104,A15,MDT!$E$5:$E$104,"נדחה — מידע חסר")) | AV15: =IF(OR(X15="",Z15=""),"",Z15-X15) | AW15: =IF(OR(Z15="",AC15=""),"",AC15-Z15) | AX15: =IF(OR(AD15="",AI15=""),"",AI15-AD15) | AY15: =IF(OR(Z15="",AI15=""),"",AI15-Z15) | AZ15: =IF(AY15="","",IF(AY15<=30,1,0)) | BA15: =IF(AY15="","",IF(AY15>60,1,0)) | BB15: =IF(AY15="","",IF(AY15>67,1,0)) | BC15: =IF(OR(AJ15<>"ניתוח",AX15=""),"",IF(AX15<=30,1,0)) | BD15: =IF(OR(AG15="",AI15="",AJ15<>"ניתוח"),"",AI15-AG15) | BE15: =IF(OR(AH15="",AI15="",AND(AJ15<>"הקרנות",AJ15<>"כימו-הקרנות")),"",AI15-AH15) | BF15: =IF(OR(AJ15<>"ניתוח",AI15="",AN15=""),"",AN15-AI15) | BG15: =IF(OR(AJ15<>"ניתוח",AI15="",AO15=""),"",AO15-AI15) | BH15: =IF(BG15="","",IF(BG15<=42,1,0))
A16: =IF(OR(B16="",C16="",D16="",Z16=""),"","HIS-"&RIGHT(YEAR(Z16),2)&"-"&TEXT(B16,"000")&"-"&C16&"-"&D16&"-"&TEXT(MONTH(Z16),"00")) | B16: 11 | E16: לא רלוונטי | AR16: =IF(A16="","",COUNTIF(MDT!$B$5:$B$104,A16)) | AS16: =IF(A16="","",COUNTIFS(MDT!$B$5:$B$104,A16,MDT!$E$5:$E$104,"נדחה — מידע חסר")) | AV16: =IF(OR(X16="",Z16=""),"",Z16-X16) | AW16: =IF(OR(Z16="",AC16=""),"",AC16-Z16) | AX16: =IF(OR(AD16="",AI16=""),"",AI16-AD16) | AY16: =IF(OR(Z16="",AI16=""),"",AI16-Z16) | AZ16: =IF(AY16="","",IF(AY16<=30,1,0)) | BA16: =IF(AY16="","",IF(AY16>60,1,0)) | BB16: =IF(AY16="","",IF(AY16>67,1,0)) | BC16: =IF(OR(AJ16<>"ניתוח",AX16=""),"",IF(AX16<=30,1,0)) | BD16: =IF(OR(AG16="",AI16="",AJ16<>"ניתוח"),"",AI16-AG16) | BE16: =IF(OR(AH16="",AI16="",AND(AJ16<>"הקרנות",AJ16<>"כימו-הקרנות")),"",AI16-AH16) | BF16: =IF(OR(AJ16<>"ניתוח",AI16="",AN16=""),"",AN16-AI16) | BG16: =IF(OR(AJ16<>"ניתוח",AI16="",AO16=""),"",AO16-AI16) | BH16: =IF(BG16="","",IF(BG16<=42,1,0))
A17: =IF(OR(B17="",C17="",D17="",Z17=""),"","HIS-"&RIGHT(YEAR(Z17),2)&"-"&TEXT(B17,"000")&"-"&C17&"-"&D17&"-"&TEXT(MONTH(Z17),"00")) | B17: 12 | E17: לא רלוונטי | AR17: =IF(A17="","",COUNTIF(MDT!$B$5:$B$104,A17)) | AS17: =IF(A17="","",COUNTIFS(MDT!$B$5:$B$104,A17,MDT!$E$5:$E$104,"נדחה — מידע חסר")) | AV17: =IF(OR(X17="",Z17=""),"",Z17-X17) | AW17: =IF(OR(Z17="",AC17=""),"",AC17-Z17) | AX17: =IF(OR(AD17="",AI17=""),"",AI17-AD17) | AY17: =IF(OR(Z17="",AI17=""),"",AI17-Z17) | AZ17: =IF(AY17="","",IF(AY17<=30,1,0)) | BA17: =IF(AY17="","",IF(AY17>60,1,0)) | BB17: =IF(AY17="","",IF(AY17>67,1,0)) | BC17: =IF(OR(AJ17<>"ניתוח",AX17=""),"",IF(AX17<=30,1,0)) | BD17: =IF(OR(AG17="",AI17="",AJ17<>"ניתוח"),"",AI17-AG17) | BE17: =IF(OR(AH17="",AI17="",AND(AJ17<>"הקרנות",AJ17<>"כימו-הקרנות")),"",AI17-AH17) | BF17: =IF(OR(AJ17<>"ניתוח",AI17="",AN17=""),"",AN17-AI17) | BG17: =IF(OR(AJ17<>"ניתוח",AI17="",AO17=""),"",AO17-AI17) | BH17: =IF(BG17="","",IF(BG17<=42,1,0))
... A65: =IF(OR(B65="",C65="",D65="",Z65=""),"","HIS-"&RIGHT(YEAR(Z65),2)&"-"&TEXT(B65,"000")&"-"&C65&"-"&D65&"-"&TEXT(MONTH(Z65),"00")) | B65: 60 | E65: לא רלוונטי | AR65: =IF(A65="","",COUNTIF(MDT!$B$5:$B$104,A65)) | AS65: =IF(A65="","",COUNTIFS(MDT!$B$5:$B$104,A65,MDT!$E$5:$E$104,"נדחה — מידע חסר")) | AV65: =IF(OR(X65="",Z65=""),"",Z65-X65) | AW65: =IF(OR(Z65="",AC65=""),"",AC65-Z65) | AX65: =IF(OR(AD65="",AI65=""),"",AI65-AD65) | AY65: =IF(OR(Z65="",AI65=""),"",AI65-Z65) | AZ65: =IF(AY65="","",IF(AY65<=30,1,0)) | BA65: =IF(AY65="","",IF(AY65>60,1,0)) | BB65: =IF(AY65="","",IF(AY65>67,1,0)) | BC65: =IF(OR(AJ65<>"ניתוח",AX65=""),"",IF(AX65<=30,1,0)) | BD65: =IF(OR(AG65="",AI65="",AJ65<>"ניתוח"),"",AI65-AG65) | BE65: =IF(OR(AH65="",AI65="",AND(AJ65<>"הקרנות",AJ65<>"כימו-הקרנות")),"",AI65-AH65) | BF65: =IF(OR(AJ65<>"ניתוח",AI65="",AN65=""),"",AN65-AI65) | BG65: =IF(OR(AJ65<>"ניתוח",AI65="",AO65=""),"",AO65-AI65) | BH65: =IF(BG65="","",IF(BG65<=42,1,0))

Sheet MDT
A1: הצגות בוועדה הרב-תחומית — כל הצגה בשורה נפרדת (כולל הצגות חוזרות)
A3: מס׳ הצגה | B3: מספר מחקר | C3: הצגה מס׳ למטופל | D3: תאריך הישיבה | E3: תוצאה | F3: סיבת דחייה | G3: שאלה קלינית מפורשת | H3: תיעוד: משתתפים | I3: תיעוד: חלופות | J3: תיעוד: עמדות | K3: תיעוד: סיכום | L3: שלמות תיעוד 18/2022
A4: pres | B4: pid | C4: n | D4: date | E4: out | F4: reason | G4: q | H4: part | I4: alt | J4: pos | K4: sum | L4: comp
A5: P-001 | B5: ENT-26-001-OT-L-06 | C5: =IF(B5="","",COUNTIF($B$5:B5,B5)) -> 1 | D5: 46184 | E5: הוחלט | L5: =IF(OR(B5="",COUNTIF(H5:K5,"?*")=0),"",COUNTIF(H5:K5,"כן")/4)
A6: P-002 | B6: ENT-26-003-FOM-M-06 | C6: =IF(B6="","",COUNTIF($B$5:B6,B6)) -> 1 | D6: 46184 | E6: הוחלט | L6: =IF(OR(B6="",COUNTIF(H6:K6,"?*")=0),"",COUNTIF(H6:K6,"כן")/4)
A7: P-003 | B7: ENT-26-005-GLT-R-06 | C7: =IF(B7="","",COUNTIF($B$5:B7,B7)) -> 1 | D7: 46184 | E7: הוחלט | L7: =IF(OR(B7="",COUNTIF(H7:K7,"?*")=0),"",COUNTIF(H7:K7,"כן")/4)
A8: P-004 | B8: ENT-26-002-NPC-M-06 | C8: =IF(B8="","",COUNTIF($B$5:B8,B8)) -> 1 | D8: 46191 | E8: הוחלט | L8: =IF(OR(B8="",COUNTIF(H8:K8,"?*")=0),"",COUNTIF(H8:K8,"כן")/4)
A9: P-005 | B9: ENT-26-004-BOT-L-06 | C9: =IF(B9="","",COUNTIF($B$5:B9,B9)) -> 1 | D9: 46191 | E9: הוחלט | L9: =IF(OR(B9="",COUNTIF(H9:K9,"?*")=0),"",COUNTIF(H9:K9,"כן")/4)
A10: P-006 | B10: ENT-26-006-GLT-L-06 | C10: =IF(B10="","",COUNTIF($B$5:B10,B10)) -> 1 | D10: 46191 | E10: הוחלט | L10: =IF(OR(B10="",COUNTIF(H10:K10,"?*")=0),"",COUNTIF(H10:K10,"כן")/4)
A11: P-007 | B11: ENT-26-008-THY-B-06 | C11: =IF(B11="","",COUNTIF($B$5:B11,B11)) -> 1 | D11: 46191 | E11: הוחלט | L11: =IF(OR(B11="",COUNTIF(H11:K11,"?*")=0),"",COUNTIF(H11:K11,"כן")/4)
A12: P-008 | B12: ENT-26-010-TON-L-06 | C12: =IF(B12="","",COUNTIF($B$5:B12,B12)) -> 1 | D12: 46191 | E12: הוחלט | L12: =IF(OR(B12="",COUNTIF(H12:K12,"?*")=0),"",COUNTIF(H12:K12,"כן")/4)
A13: P-009 | B13: ENT-26-007-HPX-R-06 | C13: =IF(B13="","",COUNTIF($B$5:B13,B13)) -> 1 | D13: 46198 | E13: נדחה — מידע חסר | L13: =IF(OR(B13="",COUNTIF(H13:K13,"?*")=0),"",COUNTIF(H13:K13,"כן")/4)
A14: P-010 | B14: ENT-26-009-HPX-L-06 | C14: =IF(B14="","",COUNTIF($B$5:B14,B14)) -> 1 | D14: 46198 | E14: נדחה — מידע חסר | L14: =IF(OR(B14="",COUNTIF(H14:K14,"?*")=0),"",COUNTIF(H14:K14,"כן")/4)
A15: P-011 | B15: ENT-26-011-PAR-R-06 | C15: =IF(B15="","",COUNTIF($B$5:B15,B15)) -> 1 | D15: 46198 | E15: הוחלט | L15: =IF(OR(B15="",COUNTIF(H15:K15,"?*")=0),"",COUNTIF(H15:K15,"כן")/4)
A16: P-012 | B16: ENT-26-013-BUC-L-06 | C16: =IF(B16="","",COUNTIF($B$5:B16,B16)) -> 1 | D16: 46198 | E16: נדחה — מידע חסר | L16: =IF(OR(B16="",COUNTIF(H16:K16,"?*")=0),"",COUNTIF(H16:K16,"כן")/4)
... A30: P-026 | B30: ENT-26-013-BUC-L-06 | C30: =IF(B30="","",COUNTIF($B$5:B30,B30)) -> 3 | D30: 46240 | E30: הוחלט | L30: =IF(OR(B30="",COUNTIF(H30:K30,"?*")=0),"",COUNTIF(H30:K30,"כן")/4)
A31: P-027 | C31: =IF(B31="","",COUNTIF($B$5:B31,B31)) | L31: =IF(OR(B31="",COUNTIF(H31:K31,"?*")=0),"",COUNTIF(H31:K31,"כן")/4)
A32: P-028 | C32: =IF(B32="","",COUNTIF($B$5:B32,B32)) | L32: =IF(OR(B32="",COUNTIF(H32:K32,"?*")=0),"",COUNTIF(H32:K32,"כן")/4)
A33: P-029 | C33: =IF(B33="","",COUNTIF($B$5:B33,B33)) | L33: =IF(OR(B33="",COUNTIF(H33:K33,"?*")=0),"",COUNTIF(H33:K33,"כן")/4)
A34: P-030 | C34: =IF(B34="","",COUNTIF($B$5:B34,B34)) | L34: =IF(OR(B34="",COUNTIF(H34:K34,"?*")=0),"",COUNTIF(H34:K34,"כן")/4)
A35: P-031 | C35: =IF(B35="","",COUNTIF($B$5:B35,B35)) | L35: =IF(OR(B35="",COUNTIF(H35:K35,"?*")=0),"",COUNTIF(H35:K35,"כן")/4)
A36: P-032 | C36: =IF(B36="","",COUNTIF($B$5:B36,B36)) | L36: =IF(OR(B36="",COUNTIF(H36:K36,"?*")=0),"",COUNTIF(H36:K36,"כן")/4)
A37: P-033 | C37: =IF(B37="","",COUNTIF($B$5:B37,B37)) | L37: =IF(OR(B37="",COUNTIF(H37:K37,"?*")=0),"",COUNTIF(H37:K37,"כן")/4)
A38: P-034 | C38: =IF(B38="","",COUNTIF($B$5:B38,B38)) | L38: =IF(OR(B38="",COUNTIF(H38:K38,"?*")=0),"",COUNTIF(H38:K38,"כן")/4)
A39: P-035 | C39: =IF(B39="","",COUNTIF($B$5:B39,B39)) | L39: =IF(OR(B39="",COUNTIF(H39:K39,"?*")=0),"",COUNTIF(H39:K39,"כן")/4)
A40: P-036 | C40: =IF(B40="","",COUNTIF($B$5:B40,B40)) | L40: =IF(OR(B40="",COUNTIF(H40:K40,"?*")=0),"",COUNTIF(H40:K40,"כן")/4)
A41: P-037 | C41: =IF(B41="","",COUNTIF($B$5:B41,B41)) | L41: =IF(OR(B41="",COUNTIF(H41:K41,"?*")=0),"",COUNTIF(H41:K41,"כן")/4)
A42: P-038 | C42: =IF(B42="","",COUNTIF($B$5:B42,B42)) | L42: =IF(OR(B42="",COUNTIF(H42:K42,"?*")=0),"",COUNTIF(H42:K42,"כן")/4)
... A104: P-100 | C104: =IF(B104="","",COUNTIF($B$5:B104,B104)) | L104: =IF(OR(B104="",COUNTIF(H104:K104,"?*")=0),"",COUNTIF(H104:K104,"כן")/4)

Sheet Loops
A1: יומן הלולאות — ייצוא מהכלי או הזנה ידנית; חותמת זמן מלאה (תאריך ושעה)
A3: מס׳ לולאה | B3: מספר מחקר | C3: שלב | D3: דיסציפלינה ממוענת | E3: סוג הלולאה | F3: נפתחה | G3: אושרה קבלה | H3: נענתה | I3: נסגרה | J3: נסגרה בידי הפותח | K3: מצב | L3: ימים עד אישור קבלה | M3: ימים עד תשובה | N3: ימים עד סגירה
A4: lid | B4: pid | C4: phase | D4: disc | E4: type | F4: op | G4: ack | H4: ans | I4: cls | J4: byop | K4: st | L4: d_ack | M4: d_ans | N4: d_cls
A5: L-001 | K5: =IF(F5="","",IF(I5<>"","נסגרה",IF(H5<>"","נענתה",IF(G5<>"","אושרה קבלה","נפתחה")))) | L5: =IF(OR(F5="",G5=""),"",G5-F5) | M5: =IF(OR(F5="",H5=""),"",H5-F5) | N5: =IF(OR(F5="",I5=""),"",I5-F5)
A6: L-002 | K6: =IF(F6="","",IF(I6<>"","נסגרה",IF(H6<>"","נענתה",IF(G6<>"","אושרה קבלה","נפתחה")))) | L6: =IF(OR(F6="",G6=""),"",G6-F6) | M6: =IF(OR(F6="",H6=""),"",H6-F6) | N6: =IF(OR(F6="",I6=""),"",I6-F6)
A7: L-003 | K7: =IF(F7="","",IF(I7<>"","נסגרה",IF(H7<>"","נענתה",IF(G7<>"","אושרה קבלה","נפתחה")))) | L7: =IF(OR(F7="",G7=""),"",G7-F7) | M7: =IF(OR(F7="",H7=""),"",H7-F7) | N7: =IF(OR(F7="",I7=""),"",I7-F7)
A8: L-004 | K8: =IF(F8="","",IF(I8<>"","נסגרה",IF(H8<>"","נענתה",IF(G8<>"","אושרה קבלה","נפתחה")))) | L8: =IF(OR(F8="",G8=""),"",G8-F8) | M8: =IF(OR(F8="",H8=""),"",H8-F8) | N8: =IF(OR(F8="",I8=""),"",I8-F8)
A9: L-005 | K9: =IF(F9="","",IF(I9<>"","נסגרה",IF(H9<>"","נענתה",IF(G9<>"","אושרה קבלה","נפתחה")))) | L9: =IF(OR(F9="",G9=""),"",G9-F9) | M9: =IF(OR(F9="",H9=""),"",H9-F9) | N9: =IF(OR(F9="",I9=""),"",I9-F9)
A10: L-006 | K10: =IF(F10="","",IF(I10<>"","נסגרה",IF(H10<>"","נענתה",IF(G10<>"","אושרה קבלה","נפתחה")))) | L10: =IF(OR(F10="",G10=""),"",G10-F10) | M10: =IF(OR(F10="",H10=""),"",H10-F10) | N10: =IF(OR(F10="",I10=""),"",I10-F10)
A11: L-007 | K11: =IF(F11="","",IF(I11<>"","נסגרה",IF(H11<>"","נענתה",IF(G11<>"","אושרה קבלה","נפתחה")))) | L11: =IF(OR(F11="",G11=""),"",G11-F11) | M11: =IF(OR(F11="",H11=""),"",H11-F11) | N11: =IF(OR(F11="",I11=""),"",I11-F11)
A12: L-008 | K12: =IF(F12="","",IF(I12<>"","נסגרה",IF(H12<>"","נענתה",IF(G12<>"","אושרה קבלה","נפתחה")))) | L12: =IF(OR(F12="",G12=""),"",G12-F12) | M12: =IF(OR(F12="",H12=""),"",H12-F12) | N12: =IF(OR(F12="",I12=""),"",I12-F12)
A13: L-009 | K13: =IF(F13="","",IF(I13<>"","נסגרה",IF(H13<>"","נענתה",IF(G13<>"","אושרה קבלה","נפתחה")))) | L13: =IF(OR(F13="",G13=""),"",G13-F13) | M13: =IF(OR(F13="",H13=""),"",H13-F13) | N13: =IF(OR(F13="",I13=""),"",I13-F13)
A14: L-010 | K14: =IF(F14="","",IF(I14<>"","נסגרה",IF(H14<>"","נענתה",IF(G14<>"","אושרה קבלה","נפתחה")))) | L14: =IF(OR(F14="",G14=""),"",G14-F14) | M14: =IF(OR(F14="",H14=""),"",H14-F14) | N14: =IF(OR(F14="",I14=""),"",I14-F14)
A15: L-011 | K15: =IF(F15="","",IF(I15<>"","נסגרה",IF(H15<>"","נענתה",IF(G15<>"","אושרה קבלה","נפתחה")))) | L15: =IF(OR(F15="",G15=""),"",G15-F15) | M15: =IF(OR(F15="",H15=""),"",H15-F15) | N15: =IF(OR(F15="",I15=""),"",I15-F15)
A16: L-012 | K16: =IF(F16="","",IF(I16<>"","נסגרה",IF(H16<>"","נענתה",IF(G16<>"","אושרה קבלה","נפתחה")))) | L16: =IF(OR(F16="",G16=""),"",G16-F16) | M16: =IF(OR(F16="",H16=""),"",H16-F16) | N16: =IF(OR(F16="",I16=""),"",I16-F16)
... A304: L-300 | K304: =IF(F304="","",IF(I304<>"","נסגרה",IF(H304<>"","נענתה",IF(G304<>"","אושרה קבלה","נפתחה")))) | L304: =IF(OR(F304="",G304=""),"",G304-F304) | M304: =IF(OR(F304="",H304=""),"",H304-F304) | N304: =IF(OR(F304="",I304=""),"",I304-F304)

Sheet Screening
A1: יומן סינון — כל מטופל עם ממאירות ראש-צוואר חדשה שנדון בוועדה (ללא פרטים מזהים)
A3: מס׳ סינון | B3: חודש אבחנה | C3: קוד אתר | D3: נדון בוועדה | E3: נפתח מקרה בכלי | F3: כשיר למחקר | G3: סיבת אי-כשירות | H3: פנו אליו | I3: חתם הסכמה | J3: מספר מחקר (אם נכלל)
A4: scr | B4: mon | C4: site | D4: mdt | E4: tool | F4: elig | G4: excl | H4: appr | I4: cons | J4: pid
A5: S-001
A6: S-002
A7: S-003
A8: S-004
A9: S-005
A10: S-006
A11: S-007
A12: S-008
A13: S-009
A14: S-010
A15: S-011
A16: S-012
... A84: S-080

Sheet Staff
A1: פעילות הצוות בכלי — ברמת דיסציפלינה בלבד (אין דיווח ברמת הפרט, סעיף 8.3)
A3: חודש | B3: דיסציפלינה | C3: חברי צוות בוועדה | D3: פעילים בכלי בחודש | E3: שיעור פעילים
A4: mon | B4: disc | C4: mem | D4: act | E4: pct
E5: =IF(OR(C5="",C5=0),"",D5/C5)
E6: =IF(OR(C6="",C6=0),"",D6/C6)
